<sdf version='1.6'>
  <world name='default'>
   <plugin name="welcome_message" filename="libwelcome_message.so"/>
    <light name='sun' type='directional'>
      <cast_shadows>1</cast_shadows>
      <pose frame=''>0 0 10 0 -0 0</pose>
      <diffuse>0.8 0.8 0.8 1</diffuse>
      <specular>0.2 0.2 0.2 1</specular>
      <attenuation>
        <range>1000</range>
        <constant>0.9</constant>
        <linear>0.01</linear>
        <quadratic>0.001</quadratic>
      </attenuation>
      <direction>-0.5 0.1 -0.9</direction>
    </light>
    <model name='ground_plane'>
      <static>1</static>
      <link name='link'>
        <collision name='collision'>
          <geometry>
            <plane>
              <normal>0 0 1</normal>
              <size>100 100</size>
            </plane>
          </geometry>
          <surface>
            <contact>
              <collide_bitmask>65535</collide_bitmask>
              <ode/>
            </contact>
            <friction>
              <ode>
                <mu>100</mu>
                <mu2>50</mu2>
              </ode>
              <torsional>
                <ode/>
              </torsional>
            </friction>
            <bounce/>
          </surface>
          <max_contacts>10</max_contacts>
        </collision>
        <visual name='visual'>
          <cast_shadows>0</cast_shadows>
          <geometry>
            <plane>
              <normal>0 0 1</normal>
              <size>100 100</size>
            </plane>
          </geometry>
          <material>
            <script>
              <uri>file://media/materials/scripts/gazebo.material</uri>
              <name>Gazebo/Grey</name>
            </script>
          </material>
        </visual>
        <self_collide>0</self_collide>
        <kinematic>0</kinematic>
      </link>
    </model>
    <gravity>0 0 -9.8</gravity>
    <magnetic_field>6e-06 2.3e-05 -4.2e-05</magnetic_field>
    <atmosphere type='adiabatic'/>
    <physics name='default_physics' default='0' type='ode'>
      <max_step_size>0.001</max_step_size>
      <real_time_factor>1</real_time_factor>
      <real_time_update_rate>1000</real_time_update_rate>
    </physics>
    <scene>
      <ambient>0.4 0.4 0.4 1</ambient>
      <background>0.7 0.7 0.7 1</background>
      <shadows>1</shadows>
    </scene>
    <spherical_coordinates>
      <surface_model>EARTH_WGS84</surface_model>
      <latitude_deg>0</latitude_deg>
      <longitude_deg>0</longitude_deg>
      <elevation>0</elevation>
      <heading_deg>0</heading_deg>
    </spherical_coordinates>
    <model name='mybuilding'>
      <pose frame=''>0.334103 -0.288985 0 0 -0 0</pose>
      <link name='Wall_21'>
        <collision name='Wall_21_Collision'>
          <geometry>
            <box>
              <size>3.25 0.15 2.5</size>
            </box>
          </geometry>
          <pose frame=''>0 0 1.25 0 -0 0</pose>
          <max_contacts>10</max_contacts>
          <surface>
            <contact>
              <ode/>
            </contact>
            <bounce/>
            <friction>
              <torsional>
                <ode/>
              </torsional>
              <ode/>
            </friction>
          </surface>
        </collision>
        <visual name='Wall_21_Visual'>
          <pose frame=''>0 0 1.25 0 -0 0</pose>
          <geometry>
            <box>
              <size>3.25 0.15 2.5</size>
            </box>
          </geometry>
          <material>
            <script>
              <uri>file://media/materials/scripts/gazebo.material</uri>
              <name>Gazebo/Wood</name>
            </script>
            <ambient>0.435294 0.796078 0.67451 1</ambient>
          </material>
          <meta>
            <layer>0</layer>
          </meta>
        </visual>
        <pose frame=''>-7.82796 -1.64563 0 0 0 -1.5708</pose>
        <self_collide>0</self_collide>
        <kinematic>0</kinematic>
      </link>
      <link name='Wall_22'>
        <pose frame=''>-6.15297 -3.19563 0 0 -0 0</pose>
        <visual name='Wall_22_Visual_0'>
          <pose frame=''>-1.48057 0 1.25 0 -0 0</pose>
          <geometry>
            <box>
              <size>0.53885 0.15 2.5</size>
            </box>
          </geometry>
          <material>
            <script>
              <uri>file://media/materials/scripts/gazebo.material</uri>
              <name>Gazebo/Wood</name>
            </script>
            <ambient>0.435294 0.796078 0.67451 1</ambient>
          </material>
          <meta>
            <layer>0</layer>
          </meta>
        </visual>
        <collision name='Wall_22_Collision_0'>
          <geometry>
            <box>
              <size>0.53885 0.15 2.5</size>
            </box>
          </geometry>
          <pose frame=''>-1.48057 0 1.25 0 -0 0</pose>
          <max_contacts>10</max_contacts>
          <surface>
            <contact>
              <ode/>
            </contact>
            <bounce/>
            <friction>
              <torsional>
                <ode/>
              </torsional>
              <ode/>
            </friction>
          </surface>
        </collision>
        <visual name='Wall_22_Visual_1'>
          <pose frame=''>0.269425 0 0.25 0 -0 0</pose>
          <geometry>
            <box>
              <size>2.96115 0.15 0.5</size>
            </box>
          </geometry>
          <material>
            <script>
              <uri>file://media/materials/scripts/gazebo.material</uri>
              <name>Gazebo/Wood</name>
            </script>
            <ambient>0.435294 0.796078 0.67451 1</ambient>
          </material>
          <meta>
            <layer>0</layer>
          </meta>
        </visual>
        <collision name='Wall_22_Collision_1'>
          <geometry>
            <box>
              <size>2.96115 0.15 0.5</size>
            </box>
          </geometry>
          <pose frame=''>0.269425 0 0.25 0 -0 0</pose>
          <max_contacts>10</max_contacts>
          <surface>
            <contact>
              <ode/>
            </contact>
            <bounce/>
            <friction>
              <torsional>
                <ode/>
              </torsional>
              <ode/>
            </friction>
          </surface>
        </collision>
        <visual name='Wall_22_Visual_2'>
          <pose frame=''>0.669425 0 1.5 0 -0 0</pose>
          <geometry>
            <box>
              <size>2.16115 0.15 2</size>
            </box>
          </geometry>
          <material>
            <script>
              <uri>file://media/materials/scripts/gazebo.material</uri>
              <name>Gazebo/Wood</name>
            </script>
            <ambient>0.435294 0.796078 0.67451 1</ambient>
          </material>
          <meta>
            <layer>0</layer>
          </meta>
        </visual>
        <collision name='Wall_22_Collision_2'>
          <geometry>
            <box>
              <size>2.16115 0.15 2</size>
            </box>
          </geometry>
          <pose frame=''>0.669425 0 1.5 0 -0 0</pose>
          <max_contacts>10</max_contacts>
          <surface>
            <contact>
              <ode/>
            </contact>
            <bounce/>
            <friction>
              <torsional>
                <ode/>
              </torsional>
              <ode/>
            </friction>
          </surface>
        </collision>
        <visual name='Wall_22_Visual_3'>
          <pose frame=''>-0.81115 0 1.9 0 -0 0</pose>
          <geometry>
            <box>
              <size>0.8 0.15 1.2</size>
            </box>
          </geometry>
          <material>
            <script>
              <uri>file://media/materials/scripts/gazebo.material</uri>
              <name>Gazebo/Wood</name>
            </script>
            <ambient>0.435294 0.796078 0.67451 1</ambient>
          </material>
          <meta>
            <layer>0</layer>
          </meta>
        </visual>
        <collision name='Wall_22_Collision_3'>
          <geometry>
            <box>
              <size>0.8 0.15 1.2</size>
            </box>
          </geometry>
          <pose frame=''>-0.81115 0 1.9 0 -0 0</pose>
          <max_contacts>10</max_contacts>
          <surface>
            <contact>
              <ode/>
            </contact>
            <bounce/>
            <friction>
              <torsional>
                <ode/>
              </torsional>
              <ode/>
            </friction>
          </surface>
        </collision>
        <self_collide>0</self_collide>
        <kinematic>0</kinematic>
      </link>
      <link name='Wall_23'>
        <pose frame=''>-4.47797 -1.64563 0 0 -0 1.5708</pose>
        <visual name='Wall_23_Visual_0'>
          <pose frame=''>-0.609459 0 1.25 0 -0 0</pose>
          <geometry>
            <box>
              <size>2.03108 0.15 2.5</size>
            </box>
          </geometry>
          <material>
            <script>
              <uri>file://media/materials/scripts/gazebo.material</uri>
              <name>Gazebo/Wood</name>
            </script>
            <ambient>0.435294 0.796078 0.67451 1</ambient>
          </material>
          <meta>
            <layer>0</layer>
          </meta>
        </visual>
        <collision name='Wall_23_Collision_0'>
          <geometry>
            <box>
              <size>2.03108 0.15 2.5</size>
            </box>
          </geometry>
          <pose frame=''>-0.609459 0 1.25 0 -0 0</pose>
          <max_contacts>10</max_contacts>
          <surface>
            <contact>
              <ode/>
            </contact>
            <bounce/>
            <friction>
              <torsional>
                <ode/>
              </torsional>
              <ode/>
            </friction>
          </surface>
        </collision>
        <visual name='Wall_23_Visual_1'>
          <pose frame=''>1.46554 0 1.25 0 -0 0</pose>
          <geometry>
            <box>
              <size>0.318918 0.15 2.5</size>
            </box>
          </geometry>
          <material>
            <script>
              <uri>file://media/materials/scripts/gazebo.material</uri>
              <name>Gazebo/Wood</name>
            </script>
            <ambient>0.435294 0.796078 0.67451 1</ambient>
          </material>
          <meta>
            <layer>0</layer>
          </meta>
        </visual>
        <collision name='Wall_23_Collision_1'>
          <geometry>
            <box>
              <size>0.318918 0.15 2.5</size>
            </box>
          </geometry>
          <pose frame=''>1.46554 0 1.25 0 -0 0</pose>
          <max_contacts>10</max_contacts>
          <surface>
            <contact>
              <ode/>
            </contact>
            <bounce/>
            <friction>
              <torsional>
                <ode/>
              </torsional>
              <ode/>
            </friction>
          </surface>
        </collision>
        <visual name='Wall_23_Visual_2'>
          <pose frame=''>0.856082 0 2.25 0 -0 0</pose>
          <geometry>
            <box>
              <size>0.9 0.15 0.5</size>
            </box>
          </geometry>
          <material>
            <script>
              <uri>file://media/materials/scripts/gazebo.material</uri>
              <name>Gazebo/Wood</name>
            </script>
            <ambient>0.435294 0.796078 0.67451 1</ambient>
          </material>
          <meta>
            <layer>0</layer>
          </meta>
        </visual>
        <collision name='Wall_23_Collision_2'>
          <geometry>
            <box>
              <size>0.9 0.15 0.5</size>
            </box>
          </geometry>
          <pose frame=''>0.856082 0 2.25 0 -0 0</pose>
          <max_contacts>10</max_contacts>
          <surface>
            <contact>
              <ode/>
            </contact>
            <bounce/>
            <friction>
              <torsional>
                <ode/>
              </torsional>
              <ode/>
            </friction>
          </surface>
        </collision>
        <self_collide>0</self_collide>
        <kinematic>0</kinematic>
      </link>
      <link name='Wall_25'>
        <collision name='Wall_25_Collision'>
          <geometry>
            <box>
              <size>3.5 0.15 2.5</size>
            </box>
          </geometry>
          <pose frame=''>0 0 1.25 0 -0 0</pose>
          <max_contacts>10</max_contacts>
          <surface>
            <contact>
              <ode/>
            </contact>
            <bounce/>
            <friction>
              <torsional>
                <ode/>
              </torsional>
              <ode/>
            </friction>
          </surface>
        </collision>
        <visual name='Wall_25_Visual'>
          <pose frame=''>0 0 1.25 0 -0 0</pose>
          <geometry>
            <box>
              <size>3.5 0.15 2.5</size>
            </box>
          </geometry>
          <material>
            <script>
              <uri>file://media/materials/scripts/gazebo.material</uri>
              <name>Gazebo/Wood</name>
            </script>
            <ambient>0.435294 0.796078 0.67451 1</ambient>
          </material>
          <meta>
            <layer>0</layer>
          </meta>
        </visual>
        <pose frame=''>-6.15297 -0.095628 0 0 -0 0</pose>
        <self_collide>0</self_collide>
        <kinematic>0</kinematic>
      </link>
      <link name='Wall_30'>
        <collision name='Wall_30_Collision'>
          <geometry>
            <box>
              <size>3.25 0.15 2.5</size>
            </box>
          </geometry>
          <pose frame=''>0 0 1.25 0 -0 0</pose>
          <max_contacts>10</max_contacts>
          <surface>
            <contact>
              <ode/>
            </contact>
            <bounce/>
            <friction>
              <torsional>
                <ode/>
              </torsional>
              <ode/>
            </friction>
          </surface>
        </collision>
        <visual name='Wall_30_Visual'>
          <pose frame=''>0 0 1.25 0 -0 0</pose>
          <geometry>
            <box>
              <size>3.25 0.15 2.5</size>
            </box>
          </geometry>
          <material>
            <script>
              <uri>file://media/materials/scripts/gazebo.material</uri>
              <name>Gazebo/Wood</name>
            </script>
            <ambient>1 1 1 1</ambient>
          </material>
          <meta>
            <layer>0</layer>
          </meta>
        </visual>
        <pose frame=''>-7.82796 1.45437 0 0 -0 1.5708</pose>
        <self_collide>0</self_collide>
        <kinematic>0</kinematic>
      </link>
      <link name='Wall_31'>
        <pose frame=''>-6.15297 3.00437 0 0 -0 0</pose>
        <visual name='Wall_31_Visual_0'>
          <pose frame=''>-1.28397 0 1.25 0 -0 0</pose>
          <geometry>
            <box>
              <size>0.932071 0.15 2.5</size>
            </box>
          </geometry>
          <material>
            <script>
              <uri>file://media/materials/scripts/gazebo.material</uri>
              <name>Gazebo/Wood</name>
            </script>
            <ambient>1 1 1 1</ambient>
          </material>
          <meta>
            <layer>0</layer>
          </meta>
        </visual>
        <collision name='Wall_31_Collision_0'>
          <geometry>
            <box>
              <size>0.932071 0.15 2.5</size>
            </box>
          </geometry>
          <pose frame=''>-1.28397 0 1.25 0 -0 0</pose>
          <max_contacts>10</max_contacts>
          <surface>
            <contact>
              <ode/>
            </contact>
            <bounce/>
            <friction>
              <torsional>
                <ode/>
              </torsional>
              <ode/>
            </friction>
          </surface>
        </collision>
        <visual name='Wall_31_Visual_1'>
          <pose frame=''>0.466035 0 0.25 0 -0 0</pose>
          <geometry>
            <box>
              <size>2.56793 0.15 0.5</size>
            </box>
          </geometry>
          <material>
            <script>
              <uri>file://media/materials/scripts/gazebo.material</uri>
              <name>Gazebo/Wood</name>
            </script>
            <ambient>1 1 1 1</ambient>
          </material>
          <meta>
            <layer>0</layer>
          </meta>
        </visual>
        <collision name='Wall_31_Collision_1'>
          <geometry>
            <box>
              <size>2.56793 0.15 0.5</size>
            </box>
          </geometry>
          <pose frame=''>0.466035 0 0.25 0 -0 0</pose>
          <max_contacts>10</max_contacts>
          <surface>
            <contact>
              <ode/>
            </contact>
            <bounce/>
            <friction>
              <torsional>
                <ode/>
              </torsional>
              <ode/>
            </friction>
          </surface>
        </collision>
        <visual name='Wall_31_Visual_2'>
          <pose frame=''>0.866035 0 1.5 0 -0 0</pose>
          <geometry>
            <box>
              <size>1.76793 0.15 2</size>
            </box>
          </geometry>
          <material>
            <script>
              <uri>file://media/materials/scripts/gazebo.material</uri>
              <name>Gazebo/Wood</name>
            </script>
            <ambient>1 1 1 1</ambient>
          </material>
          <meta>
            <layer>0</layer>
          </meta>
        </visual>
        <collision name='Wall_31_Collision_2'>
          <geometry>
            <box>
              <size>1.76793 0.15 2</size>
            </box>
          </geometry>
          <pose frame=''>0.866035 0 1.5 0 -0 0</pose>
          <max_contacts>10</max_contacts>
          <surface>
            <contact>
              <ode/>
            </contact>
            <bounce/>
            <friction>
              <torsional>
                <ode/>
              </torsional>
              <ode/>
            </friction>
          </surface>
        </collision>
        <visual name='Wall_31_Visual_3'>
          <pose frame=''>-0.417929 0 1.9 0 -0 0</pose>
          <geometry>
            <box>
              <size>0.8 0.15 1.2</size>
            </box>
          </geometry>
          <material>
            <script>
              <uri>file://media/materials/scripts/gazebo.material</uri>
              <name>Gazebo/Wood</name>
            </script>
            <ambient>1 1 1 1</ambient>
          </material>
          <meta>
            <layer>0</layer>
          </meta>
        </visual>
        <collision name='Wall_31_Collision_3'>
          <geometry>
            <box>
              <size>0.8 0.15 1.2</size>
            </box>
          </geometry>
          <pose frame=''>-0.417929 0 1.9 0 -0 0</pose>
          <max_contacts>10</max_contacts>
          <surface>
            <contact>
              <ode/>
            </contact>
            <bounce/>
            <friction>
              <torsional>
                <ode/>
              </torsional>
              <ode/>
            </friction>
          </surface>
        </collision>
        <self_collide>0</self_collide>
        <kinematic>0</kinematic>
      </link>
      <link name='Wall_32'>
        <collision name='Wall_32_Collision'>
          <geometry>
            <box>
              <size>2 0.15 2.5</size>
            </box>
          </geometry>
          <pose frame=''>0 0 1.25 0 -0 0</pose>
          <max_contacts>10</max_contacts>
          <surface>
            <contact>
              <ode/>
            </contact>
            <bounce/>
            <friction>
              <torsional>
                <ode/>
              </torsional>
              <ode/>
            </friction>
          </surface>
        </collision>
        <visual name='Wall_32_Visual'>
          <pose frame=''>0 0 1.25 0 -0 0</pose>
          <geometry>
            <box>
              <size>2 0.15 2.5</size>
            </box>
          </geometry>
          <material>
            <script>
              <uri>file://media/materials/scripts/gazebo.material</uri>
              <name>Gazebo/Wood</name>
            </script>
            <ambient>1 1 1 1</ambient>
          </material>
          <meta>
            <layer>0</layer>
          </meta>
        </visual>
        <pose frame=''>-4.47797 2.07937 0 0 0 -1.5708</pose>
        <self_collide>0</self_collide>
        <kinematic>0</kinematic>
      </link>
      <link name='Wall_33'>
        <collision name='Wall_33_Collision'>
          <geometry>
            <box>
              <size>5 0.15 2.5</size>
            </box>
          </geometry>
          <pose frame=''>0 0 1.25 0 -0 0</pose>
          <max_contacts>10</max_contacts>
          <surface>
            <contact>
              <ode/>
            </contact>
            <bounce/>
            <friction>
              <torsional>
                <ode/>
              </torsional>
              <ode/>
            </friction>
          </surface>
        </collision>
        <visual name='Wall_33_Visual'>
          <pose frame=''>0 0 1.25 0 -0 0</pose>
          <geometry>
            <box>
              <size>5 0.15 2.5</size>
            </box>
          </geometry>
          <material>
            <script>
              <uri>file://media/materials/scripts/gazebo.material</uri>
              <name>Gazebo/Wood</name>
            </script>
            <ambient>1 1 1 1</ambient>
          </material>
          <meta>
            <layer>0</layer>
          </meta>
        </visual>
        <pose frame=''>-2.05296 1.15437 0 0 -0 0</pose>
        <self_collide>0</self_collide>
        <kinematic>0</kinematic>
      </link>
      <link name='Wall_34'>
        <collision name='Wall_34_Collision'>
          <geometry>
            <box>
              <size>2.25 0.15 2.5</size>
            </box>
          </geometry>
          <pose frame=''>0 0 1.25 0 -0 0</pose>
          <max_contacts>10</max_contacts>
          <surface>
            <contact>
              <ode/>
            </contact>
            <bounce/>
            <friction>
              <torsional>
                <ode/>
              </torsional>
              <ode/>
            </friction>
          </surface>
        </collision>
        <visual name='Wall_34_Visual'>
          <pose frame=''>0 0 1.25 0 -0 0</pose>
          <geometry>
            <box>
              <size>2.25 0.15 2.5</size>
            </box>
          </geometry>
          <material>
            <script>
              <uri>file://media/materials/scripts/gazebo.material</uri>
              <name>Gazebo/Wood</name>
            </script>
            <ambient>1 1 1 1</ambient>
          </material>
          <meta>
            <layer>0</layer>
          </meta>
        </visual>
        <pose frame=''>0.372035 2.20437 0 0 -0 1.5708</pose>
        <self_collide>0</self_collide>
        <kinematic>0</kinematic>
      </link>
      <link name='Wall_35'>
        <pose frame=''>1.54703 3.25437 0 0 -0 0</pose>
        <visual name='Wall_35_Visual_0'>
          <pose frame=''>-0.872674 0 1.25 0 -0 0</pose>
          <geometry>
            <box>
              <size>0.754653 0.15 2.5</size>
            </box>
          </geometry>
          <material>
            <script>
              <uri>file://media/materials/scripts/gazebo.material</uri>
              <name>Gazebo/Wood</name>
            </script>
            <ambient>1 1 1 1</ambient>
          </material>
          <meta>
            <layer>0</layer>
          </meta>
        </visual>
        <collision name='Wall_35_Collision_0'>
          <geometry>
            <box>
              <size>0.754653 0.15 2.5</size>
            </box>
          </geometry>
          <pose frame=''>-0.872674 0 1.25 0 -0 0</pose>
          <max_contacts>10</max_contacts>
          <surface>
            <contact>
              <ode/>
            </contact>
            <bounce/>
            <friction>
              <torsional>
                <ode/>
              </torsional>
              <ode/>
            </friction>
          </surface>
        </collision>
        <visual name='Wall_35_Visual_1'>
          <pose frame=''>0.827326 0 1.25 0 -0 0</pose>
          <geometry>
            <box>
              <size>0.845347 0.15 2.5</size>
            </box>
          </geometry>
          <material>
            <script>
              <uri>file://media/materials/scripts/gazebo.material</uri>
              <name>Gazebo/Wood</name>
            </script>
            <ambient>1 1 1 1</ambient>
          </material>
          <meta>
            <layer>0</layer>
          </meta>
        </visual>
        <collision name='Wall_35_Collision_1'>
          <geometry>
            <box>
              <size>0.845347 0.15 2.5</size>
            </box>
          </geometry>
          <pose frame=''>0.827326 0 1.25 0 -0 0</pose>
          <max_contacts>10</max_contacts>
          <surface>
            <contact>
              <ode/>
            </contact>
            <bounce/>
            <friction>
              <torsional>
                <ode/>
              </torsional>
              <ode/>
            </friction>
          </surface>
        </collision>
        <visual name='Wall_35_Visual_2'>
          <pose frame=''>-0.045347 0 2.25 0 -0 0</pose>
          <geometry>
            <box>
              <size>0.9 0.15 0.5</size>
            </box>
          </geometry>
          <material>
            <script>
              <uri>file://media/materials/scripts/gazebo.material</uri>
              <name>Gazebo/Wood</name>
            </script>
            <ambient>1 1 1 1</ambient>
          </material>
          <meta>
            <layer>0</layer>
          </meta>
        </visual>
        <collision name='Wall_35_Collision_2'>
          <geometry>
            <box>
              <size>0.9 0.15 0.5</size>
            </box>
          </geometry>
          <pose frame=''>-0.045347 0 2.25 0 -0 0</pose>
          <max_contacts>10</max_contacts>
          <surface>
            <contact>
              <ode/>
            </contact>
            <bounce/>
            <friction>
              <torsional>
                <ode/>
              </torsional>
              <ode/>
            </friction>
          </surface>
        </collision>
        <self_collide>0</self_collide>
        <kinematic>0</kinematic>
      </link>
      <link name='Wall_36'>
        <collision name='Wall_36_Collision'>
          <geometry>
            <box>
              <size>3.25 0.15 2.5</size>
            </box>
          </geometry>
          <pose frame=''>0 0 1.25 0 -0 0</pose>
          <max_contacts>10</max_contacts>
          <surface>
            <contact>
              <ode/>
            </contact>
            <bounce/>
            <friction>
              <torsional>
                <ode/>
              </torsional>
              <ode/>
            </friction>
          </surface>
        </collision>
        <visual name='Wall_36_Visual'>
          <pose frame=''>0 0 1.25 0 -0 0</pose>
          <geometry>
            <box>
              <size>3.25 0.15 2.5</size>
            </box>
          </geometry>
          <material>
            <script>
              <uri>file://media/materials/scripts/gazebo.material</uri>
              <name>Gazebo/Wood</name>
            </script>
            <ambient>0.435294 0.796078 0.67451 1</ambient>
          </material>
          <meta>
            <layer>0</layer>
          </meta>
        </visual>
        <pose frame=''>2.72203 1.70437 0 0 0 -1.5708</pose>
        <self_collide>0</self_collide>
        <kinematic>0</kinematic>
      </link>
      <link name='Wall_38'>
        <collision name='Wall_38_Collision'>
          <geometry>
            <box>
              <size>5.25 0.15 2.5</size>
            </box>
          </geometry>
          <pose frame=''>0 0 1.25 0 -0 0</pose>
          <max_contacts>10</max_contacts>
          <surface>
            <contact>
              <ode/>
            </contact>
            <bounce/>
            <friction>
              <torsional>
                <ode/>
              </torsional>
              <ode/>
            </friction>
          </surface>
        </collision>
        <visual name='Wall_38_Visual'>
          <pose frame=''>0 0 1.25 0 -0 0</pose>
          <geometry>
            <box>
              <size>5.25 0.15 2.5</size>
            </box>
          </geometry>
          <material>
            <script>
              <uri>file://media/materials/scripts/gazebo.material</uri>
              <name>Gazebo/Wood</name>
            </script>
            <ambient>0.435294 0.796078 0.67451 1</ambient>
          </material>
          <meta>
            <layer>0</layer>
          </meta>
        </visual>
        <pose frame=''>5.27761 1.34598 0 0 -0 0</pose>
        <self_collide>0</self_collide>
        <kinematic>0</kinematic>
      </link>
      <link name='Wall_39'>
        <pose frame=''>7.82761 -0.954017 0 0 0 -1.5708</pose>
        <visual name='Wall_39_Visual_0'>
          <pose frame=''>-1.85515 0 1.25 0 -0 0</pose>
          <geometry>
            <box>
              <size>1.03971 0.15 2.5</size>
            </box>
          </geometry>
          <material>
            <script>
              <uri>file://media/materials/scripts/gazebo.material</uri>
              <name>Gazebo/Wood</name>
            </script>
            <ambient>0.435294 0.796078 0.67451 1</ambient>
          </material>
          <meta>
            <layer>0</layer>
          </meta>
        </visual>
        <collision name='Wall_39_Collision_0'>
          <geometry>
            <box>
              <size>1.03971 0.15 2.5</size>
            </box>
          </geometry>
          <pose frame=''>-1.85515 0 1.25 0 -0 0</pose>
          <max_contacts>10</max_contacts>
          <surface>
            <contact>
              <ode/>
            </contact>
            <bounce/>
            <friction>
              <torsional>
                <ode/>
              </torsional>
              <ode/>
            </friction>
          </surface>
        </collision>
        <visual name='Wall_39_Visual_1'>
          <pose frame=''>0.519853 0 0.25 0 -0 0</pose>
          <geometry>
            <box>
              <size>3.71029 0.15 0.5</size>
            </box>
          </geometry>
          <material>
            <script>
              <uri>file://media/materials/scripts/gazebo.material</uri>
              <name>Gazebo/Wood</name>
            </script>
            <ambient>0.435294 0.796078 0.67451 1</ambient>
          </material>
          <meta>
            <layer>0</layer>
          </meta>
        </visual>
        <collision name='Wall_39_Collision_1'>
          <geometry>
            <box>
              <size>3.71029 0.15 0.5</size>
            </box>
          </geometry>
          <pose frame=''>0.519853 0 0.25 0 -0 0</pose>
          <max_contacts>10</max_contacts>
          <surface>
            <contact>
              <ode/>
            </contact>
            <bounce/>
            <friction>
              <torsional>
                <ode/>
              </torsional>
              <ode/>
            </friction>
          </surface>
        </collision>
        <visual name='Wall_39_Visual_2'>
          <pose frame=''>-0.0332 0 1.5 0 -0 0</pose>
          <geometry>
            <box>
              <size>1.00419 0.15 2</size>
            </box>
          </geometry>
          <material>
            <script>
              <uri>file://media/materials/scripts/gazebo.material</uri>
              <name>Gazebo/Wood</name>
            </script>
            <ambient>0.435294 0.796078 0.67451 1</ambient>
          </material>
          <meta>
            <layer>0</layer>
          </meta>
        </visual>
        <collision name='Wall_39_Collision_2'>
          <geometry>
            <box>
              <size>1.00419 0.15 2</size>
            </box>
          </geometry>
          <pose frame=''>-0.0332 0 1.5 0 -0 0</pose>
          <max_contacts>10</max_contacts>
          <surface>
            <contact>
              <ode/>
            </contact>
            <bounce/>
            <friction>
              <torsional>
                <ode/>
              </torsional>
              <ode/>
            </friction>
          </surface>
        </collision>
        <visual name='Wall_39_Visual_3'>
          <pose frame=''>1.82195 0 1.5 0 -0 0</pose>
          <geometry>
            <box>
              <size>1.10611 0.15 2</size>
            </box>
          </geometry>
          <material>
            <script>
              <uri>file://media/materials/scripts/gazebo.material</uri>
              <name>Gazebo/Wood</name>
            </script>
            <ambient>0.435294 0.796078 0.67451 1</ambient>
          </material>
          <meta>
            <layer>0</layer>
          </meta>
        </visual>
        <collision name='Wall_39_Collision_3'>
          <geometry>
            <box>
              <size>1.10611 0.15 2</size>
            </box>
          </geometry>
          <pose frame=''>1.82195 0 1.5 0 -0 0</pose>
          <max_contacts>10</max_contacts>
          <surface>
            <contact>
              <ode/>
            </contact>
            <bounce/>
            <friction>
              <torsional>
                <ode/>
              </torsional>
              <ode/>
            </friction>
          </surface>
        </collision>
        <visual name='Wall_39_Visual_4'>
          <pose frame=''>-0.935294 0 1.9 0 -0 0</pose>
          <geometry>
            <box>
              <size>0.8 0.15 1.2</size>
            </box>
          </geometry>
          <material>
            <script>
              <uri>file://media/materials/scripts/gazebo.material</uri>
              <name>Gazebo/Wood</name>
            </script>
            <ambient>0.435294 0.796078 0.67451 1</ambient>
          </material>
          <meta>
            <layer>0</layer>
          </meta>
        </visual>
        <collision name='Wall_39_Collision_4'>
          <geometry>
            <box>
              <size>0.8 0.15 1.2</size>
            </box>
          </geometry>
          <pose frame=''>-0.935294 0 1.9 0 -0 0</pose>
          <max_contacts>10</max_contacts>
          <surface>
            <contact>
              <ode/>
            </contact>
            <bounce/>
            <friction>
              <torsional>
                <ode/>
              </torsional>
              <ode/>
            </friction>
          </surface>
        </collision>
        <visual name='Wall_39_Visual_5'>
          <pose frame=''>0.868893 0 1.9 0 -0 0</pose>
          <geometry>
            <box>
              <size>0.8 0.15 1.2</size>
            </box>
          </geometry>
          <material>
            <script>
              <uri>file://media/materials/scripts/gazebo.material</uri>
              <name>Gazebo/Wood</name>
            </script>
            <ambient>0.435294 0.796078 0.67451 1</ambient>
          </material>
          <meta>
            <layer>0</layer>
          </meta>
        </visual>
        <collision name='Wall_39_Collision_5'>
          <geometry>
            <box>
              <size>0.8 0.15 1.2</size>
            </box>
          </geometry>
          <pose frame=''>0.868893 0 1.9 0 -0 0</pose>
          <max_contacts>10</max_contacts>
          <surface>
            <contact>
              <ode/>
            </contact>
            <bounce/>
            <friction>
              <torsional>
                <ode/>
              </torsional>
              <ode/>
            </friction>
          </surface>
        </collision>
        <self_collide>0</self_collide>
        <kinematic>0</kinematic>
      </link>
      <link name='Wall_40'>
        <pose frame=''>1.67482 -3.22482 0 0 -0 3.13685</pose>
        <visual name='Wall_40_Visual_0'>
          <pose frame=''>-5.2976 0 1.25 0 -0 0</pose>
          <geometry>
            <box>
              <size>1.86051 0.15 2.5</size>
            </box>
          </geometry>
          <material>
            <script>
              <uri>file://media/materials/scripts/gazebo.material</uri>
              <name>Gazebo/Wood</name>
            </script>
            <ambient>1 1 1 1</ambient>
          </material>
          <meta>
            <layer>0</layer>
          </meta>
        </visual>
        <collision name='Wall_40_Collision_0'>
          <geometry>
            <box>
              <size>1.86051 0.15 2.5</size>
            </box>
          </geometry>
          <pose frame=''>-5.2976 0 1.25 0 -0 0</pose>
          <max_contacts>10</max_contacts>
          <surface>
            <contact>
              <ode/>
            </contact>
            <bounce/>
            <friction>
              <torsional>
                <ode/>
              </torsional>
              <ode/>
            </friction>
          </surface>
        </collision>
        <visual name='Wall_40_Visual_1'>
          <pose frame=''>0.930252 0 0.25 0 -0 0</pose>
          <geometry>
            <box>
              <size>10.5952 0.15 0.5</size>
            </box>
          </geometry>
          <material>
            <script>
              <uri>file://media/materials/scripts/gazebo.material</uri>
              <name>Gazebo/Wood</name>
            </script>
            <ambient>1 1 1 1</ambient>
          </material>
          <meta>
            <layer>0</layer>
          </meta>
        </visual>
        <collision name='Wall_40_Collision_1'>
          <geometry>
            <box>
              <size>10.5952 0.15 0.5</size>
            </box>
          </geometry>
          <pose frame=''>0.930252 0 0.25 0 -0 0</pose>
          <max_contacts>10</max_contacts>
          <surface>
            <contact>
              <ode/>
            </contact>
            <bounce/>
            <friction>
              <torsional>
                <ode/>
              </torsional>
              <ode/>
            </friction>
          </surface>
        </collision>
        <visual name='Wall_40_Visual_2'>
          <pose frame=''>-0.844536 0 1.5 0 -0 0</pose>
          <geometry>
            <box>
              <size>5.44563 0.15 2</size>
            </box>
          </geometry>
          <material>
            <script>
              <uri>file://media/materials/scripts/gazebo.material</uri>
              <name>Gazebo/Wood</name>
            </script>
            <ambient>1 1 1 1</ambient>
          </material>
          <meta>
            <layer>0</layer>
          </meta>
        </visual>
        <collision name='Wall_40_Collision_2'>
          <geometry>
            <box>
              <size>5.44563 0.15 2</size>
            </box>
          </geometry>
          <pose frame=''>-0.844536 0 1.5 0 -0 0</pose>
          <max_contacts>10</max_contacts>
          <surface>
            <contact>
              <ode/>
            </contact>
            <bounce/>
            <friction>
              <torsional>
                <ode/>
              </torsional>
              <ode/>
            </friction>
          </surface>
        </collision>
        <visual name='Wall_40_Visual_3'>
          <pose frame=''>4.45307 0 1.5 0 -0 0</pose>
          <geometry>
            <box>
              <size>3.54958 0.15 2</size>
            </box>
          </geometry>
          <material>
            <script>
              <uri>file://media/materials/scripts/gazebo.material</uri>
              <name>Gazebo/Wood</name>
            </script>
            <ambient>1 1 1 1</ambient>
          </material>
          <meta>
            <layer>0</layer>
          </meta>
        </visual>
        <collision name='Wall_40_Collision_3'>
          <geometry>
            <box>
              <size>3.54958 0.15 2</size>
            </box>
          </geometry>
          <pose frame=''>4.45307 0 1.5 0 -0 0</pose>
          <max_contacts>10</max_contacts>
          <surface>
            <contact>
              <ode/>
            </contact>
            <bounce/>
            <friction>
              <torsional>
                <ode/>
              </torsional>
              <ode/>
            </friction>
          </surface>
        </collision>
        <visual name='Wall_40_Visual_4'>
          <pose frame=''>-3.96735 0 1.9 0 -0 0</pose>
          <geometry>
            <box>
              <size>0.8 0.15 1.2</size>
            </box>
          </geometry>
          <material>
            <script>
              <uri>file://media/materials/scripts/gazebo.material</uri>
              <name>Gazebo/Wood</name>
            </script>
            <ambient>1 1 1 1</ambient>
          </material>
          <meta>
            <layer>0</layer>
          </meta>
        </visual>
        <collision name='Wall_40_Collision_4'>
          <geometry>
            <box>
              <size>0.8 0.15 1.2</size>
            </box>
          </geometry>
          <pose frame=''>-3.96735 0 1.9 0 -0 0</pose>
          <max_contacts>10</max_contacts>
          <surface>
            <contact>
              <ode/>
            </contact>
            <bounce/>
            <friction>
              <torsional>
                <ode/>
              </torsional>
              <ode/>
            </friction>
          </surface>
        </collision>
        <visual name='Wall_40_Visual_5'>
          <pose frame=''>2.27828 0 1.9 0 -0 0</pose>
          <geometry>
            <box>
              <size>0.8 0.15 1.2</size>
            </box>
          </geometry>
          <material>
            <script>
              <uri>file://media/materials/scripts/gazebo.material</uri>
              <name>Gazebo/Wood</name>
            </script>
            <ambient>1 1 1 1</ambient>
          </material>
          <meta>
            <layer>0</layer>
          </meta>
        </visual>
        <collision name='Wall_40_Collision_5'>
          <geometry>
            <box>
              <size>0.8 0.15 1.2</size>
            </box>
          </geometry>
          <pose frame=''>2.27828 0 1.9 0 -0 0</pose>
          <max_contacts>10</max_contacts>
          <surface>
            <contact>
              <ode/>
            </contact>
            <bounce/>
            <friction>
              <torsional>
                <ode/>
              </torsional>
              <ode/>
            </friction>
          </surface>
        </collision>
        <self_collide>0</self_collide>
        <kinematic>0</kinematic>
      </link>
      <link name='Wall_42'>
        <pose frame=''>2.72203 -1.52063 0 0 0 -1.5708</pose>
        <visual name='Wall_42_Visual_0'>
          <pose frame=''>0 0 1.25 0 -0 0</pose>
          <geometry>
            <box>
              <size>3.5 0.15 2.5</size>
            </box>
          </geometry>
          <material>
            <script>
              <uri>file://media/materials/scripts/gazebo.material</uri>
              <name>Gazebo/Wood</name>
            </script>
            <ambient>0.435294 0.796078 0.67451 1</ambient>
          </material>
          <meta>
            <layer>0</layer>
          </meta>
        </visual>
        <collision name='Wall_42_Collision_0'>
          <geometry>
            <box>
              <size>3.5 0.15 2.5</size>
            </box>
          </geometry>
          <pose frame=''>0 0 1.25 0 -0 0</pose>
          <max_contacts>10</max_contacts>
          <surface>
            <contact>
              <ode/>
            </contact>
            <bounce/>
            <friction>
              <torsional>
                <ode/>
              </torsional>
              <ode/>
            </friction>
          </surface>
        </collision>
        <visual name='Wall_42_Visual_1'>
          <pose frame=''>0.314351 0 1.25 0 -0 0</pose>
          <geometry>
            <box>
              <size>2.8713 0.15 2.5</size>
            </box>
          </geometry>
          <material>
            <script>
              <uri>file://media/materials/scripts/gazebo.material</uri>
              <name>Gazebo/Wood</name>
            </script>
            <ambient>0.435294 0.796078 0.67451 1</ambient>
          </material>
          <meta>
            <layer>0</layer>
          </meta>
        </visual>
        <collision name='Wall_42_Collision_1'>
          <geometry>
            <box>
              <size>2.8713 0.15 2.5</size>
            </box>
          </geometry>
          <pose frame=''>0.314351 0 1.25 0 -0 0</pose>
          <max_contacts>10</max_contacts>
          <surface>
            <contact>
              <ode/>
            </contact>
            <bounce/>
            <friction>
              <torsional>
                <ode/>
              </torsional>
              <ode/>
            </friction>
          </surface>
        </collision>
        <self_collide>0</self_collide>
        <kinematic>0</kinematic>
      </link>
      <static>1</static>
    </model>
    <model name='4wheeled-car'>
      <link name='link_1'>
        <pose frame=''>0 1e-06 0 0 -0 0</pose>
        <inertial>
          <mass>1</mass>
          <inertia>
            <ixx>0.166667</ixx>
            <ixy>0</ixy>
            <ixz>0</ixz>
            <iyy>0.166667</iyy>
            <iyz>0</iyz>
            <izz>0.166667</izz>
          </inertia>
          <pose frame=''>0 0 0 0 -0 0</pose>
        </inertial>
        <gravity>1</gravity>
        <self_collide>0</self_collide>
        <kinematic>0</kinematic>
        <visual name='visual'>
          <pose frame=''>0 0 0 0 -0 0</pose>
          <geometry>
            <box>
              <size>0.6 0.3 0.15</size>
            </box>
          </geometry>
          <material>
            <lighting>1</lighting>
            <script>
              <uri>file://media/materials/scripts/gazebo.material</uri>
              <name>Gazebo/Grey</name>
            </script>
            <shader type='pixel'>
              <normal_map>__default__</normal_map>
            </shader>
            <ambient>0.3 0.3 0.3 1</ambient>
            <diffuse>0.7 0.7 0.7 1</diffuse>
            <specular>0.01 0.01 0.01 1</specular>
            <emissive>0 0 0 1</emissive>
          </material>
          <transparency>0</transparency>
          <cast_shadows>1</cast_shadows>
        </visual>
        <collision name='collision'>
          <laser_retro>0</laser_retro>
          <max_contacts>10</max_contacts>
          <pose frame=''>0 0 0 0 -0 0</pose>
          <geometry>
            <box>
              <size>0.6 0.3 0.15</size>
            </box>
          </geometry>
          <surface>
            <friction>
              <ode>
                <mu>1</mu>
                <mu2>1</mu2>
                <fdir1>0 0 0</fdir1>
                <slip1>0</slip1>
                <slip2>0</slip2>
              </ode>
              <torsional>
                <coefficient>1</coefficient>
                <patch_radius>0</patch_radius>
                <surface_radius>0</surface_radius>
                <use_patch_radius>1</use_patch_radius>
                <ode>
                  <slip>0</slip>
                </ode>
              </torsional>
            </friction>
            <bounce>
              <restitution_coefficient>0</restitution_coefficient>
              <threshold>1e+06</threshold>
            </bounce>
            <contact>
              <collide_without_contact>0</collide_without_contact>
              <collide_without_contact_bitmask>1</collide_without_contact_bitmask>
              <collide_bitmask>1</collide_bitmask>
              <ode>
                <soft_cfm>0</soft_cfm>
                <soft_erp>0.2</soft_erp>
                <kp>1e+13</kp>
                <kd>1</kd>
                <max_vel>0.01</max_vel>
                <min_depth>0</min_depth>
              </ode>
              <bullet>
                <split_impulse>1</split_impulse>
                <split_impulse_penetration_threshold>-0.01</split_impulse_penetration_threshold>
                <soft_cfm>0</soft_cfm>
                <soft_erp>0.2</soft_erp>
                <kp>1e+13</kp>
                <kd>1</kd>
              </bullet>
            </contact>
          </surface>
        </collision>
      </link>
      <link name='link_4'>
        <pose frame=''>-0.2 -0.175013 0 1.5707 -0 0</pose>
        <inertial>
          <mass>1</mass>
          <inertia>
            <ixx>0.145833</ixx>
            <ixy>0</ixy>
            <ixz>0</ixz>
            <iyy>0.145833</iyy>
            <iyz>0</iyz>
            <izz>0.125</izz>
          </inertia>
          <pose frame=''>0 0 0 0 -0 0</pose>
        </inertial>
        <gravity>1</gravity>
        <self_collide>0</self_collide>
        <kinematic>0</kinematic>
        <visual name='visual'>
          <pose frame=''>0 0 0 0 -0 0</pose>
          <geometry>
            <cylinder>
              <radius>0.1</radius>
              <length>0.05</length>
            </cylinder>
          </geometry>
          <material>
            <lighting>1</lighting>
            <script>
              <uri>file://media/materials/scripts/gazebo.material</uri>
              <name>Gazebo/Grey</name>
            </script>
            <shader type='pixel'>
              <normal_map>__default__</normal_map>
            </shader>
            <ambient>0.3 0.3 0.3 1</ambient>
            <diffuse>0.7 0.7 0.7 1</diffuse>
            <specular>0.01 0.01 0.01 1</specular>
            <emissive>0 0 0 1</emissive>
          </material>
          <transparency>0</transparency>
          <cast_shadows>1</cast_shadows>
        </visual>
        <collision name='collision'>
          <laser_retro>0</laser_retro>
          <max_contacts>10</max_contacts>
          <pose frame=''>0 0 0 0 -0 0</pose>
          <geometry>
            <cylinder>
              <radius>0.1</radius>
              <length>0.05</length>
            </cylinder>
          </geometry>
          <surface>
            <friction>
              <ode>
                <mu>1</mu>
                <mu2>1</mu2>
                <fdir1>0 0 0</fdir1>
                <slip1>0</slip1>
                <slip2>0</slip2>
              </ode>
              <torsional>
                <coefficient>1</coefficient>
                <patch_radius>0</patch_radius>
                <surface_radius>0</surface_radius>
                <use_patch_radius>1</use_patch_radius>
                <ode>
                  <slip>0</slip>
                </ode>
              </torsional>
            </friction>
            <bounce>
              <restitution_coefficient>0</restitution_coefficient>
              <threshold>1e+06</threshold>
            </bounce>
            <contact>
              <collide_without_contact>0</collide_without_contact>
              <collide_without_contact_bitmask>1</collide_without_contact_bitmask>
              <collide_bitmask>1</collide_bitmask>
              <ode>
                <soft_cfm>0</soft_cfm>
                <soft_erp>0.2</soft_erp>
                <kp>1e+13</kp>
                <kd>1</kd>
                <max_vel>0.01</max_vel>
                <min_depth>0</min_depth>
              </ode>
              <bullet>
                <split_impulse>1</split_impulse>
                <split_impulse_penetration_threshold>-0.01</split_impulse_penetration_threshold>
                <soft_cfm>0</soft_cfm>
                <soft_erp>0.2</soft_erp>
                <kp>1e+13</kp>
                <kd>1</kd>
              </bullet>
            </contact>
          </surface>
        </collision>
      </link>
      <link name='link_4_clone'>
        <pose frame=''>0.2 -0.175009 0 1.5707 -0 0</pose>
        <inertial>
          <mass>1</mass>
          <inertia>
            <ixx>0.145833</ixx>
            <ixy>0</ixy>
            <ixz>0</ixz>
            <iyy>0.145833</iyy>
            <iyz>0</iyz>
            <izz>0.125</izz>
          </inertia>
          <pose frame=''>0 0 0 0 -0 0</pose>
        </inertial>
        <self_collide>0</self_collide>
        <kinematic>0</kinematic>
        <visual name='visual'>
          <pose frame=''>0 0 0 0 -0 0</pose>
          <geometry>
            <cylinder>
              <radius>0.1</radius>
              <length>0.05</length>
            </cylinder>
          </geometry>
          <material>
            <lighting>1</lighting>
            <script>
              <uri>file://media/materials/scripts/gazebo.material</uri>
              <name>Gazebo/Grey</name>
            </script>
            <shader type='pixel'>
              <normal_map>__default__</normal_map>
            </shader>
            <ambient>0.3 0.3 0.3 1</ambient>
            <diffuse>0.7 0.7 0.7 1</diffuse>
            <specular>0.01 0.01 0.01 1</specular>
            <emissive>0 0 0 1</emissive>
          </material>
          <transparency>0</transparency>
          <cast_shadows>1</cast_shadows>
        </visual>
        <collision name='collision'>
          <laser_retro>0</laser_retro>
          <max_contacts>10</max_contacts>
          <pose frame=''>0 0 0 0 -0 0</pose>
          <geometry>
            <cylinder>
              <radius>0.1</radius>
              <length>0.05</length>
            </cylinder>
          </geometry>
          <surface>
            <friction>
              <ode>
                <mu>1</mu>
                <mu2>1</mu2>
                <fdir1>0 0 0</fdir1>
                <slip1>0</slip1>
                <slip2>0</slip2>
              </ode>
              <torsional>
                <coefficient>1</coefficient>
                <patch_radius>0</patch_radius>
                <surface_radius>0</surface_radius>
                <use_patch_radius>1</use_patch_radius>
                <ode>
                  <slip>0</slip>
                </ode>
              </torsional>
            </friction>
            <bounce>
              <restitution_coefficient>0</restitution_coefficient>
              <threshold>1e+06</threshold>
            </bounce>
            <contact>
              <collide_without_contact>0</collide_without_contact>
              <collide_without_contact_bitmask>1</collide_without_contact_bitmask>
              <collide_bitmask>1</collide_bitmask>
              <ode>
                <soft_cfm>0</soft_cfm>
                <soft_erp>0.2</soft_erp>
                <kp>1e+13</kp>
                <kd>1</kd>
                <max_vel>0.01</max_vel>
                <min_depth>0</min_depth>
              </ode>
              <bullet>
                <split_impulse>1</split_impulse>
                <split_impulse_penetration_threshold>-0.01</split_impulse_penetration_threshold>
                <soft_cfm>0</soft_cfm>
                <soft_erp>0.2</soft_erp>
                <kp>1e+13</kp>
                <kd>1</kd>
              </bullet>
            </contact>
          </surface>
        </collision>
      </link>
      <link name='link_4_clone_0'>
        <pose frame=''>-0.2 0.175011 0 1.5707 -0 0</pose>
        <inertial>
          <mass>1</mass>
          <inertia>
            <ixx>0.145833</ixx>
            <ixy>0</ixy>
            <ixz>0</ixz>
            <iyy>0.145833</iyy>
            <iyz>0</iyz>
            <izz>0.125</izz>
          </inertia>
          <pose frame=''>0 0 0 0 -0 0</pose>
        </inertial>
        <self_collide>0</self_collide>
        <kinematic>0</kinematic>
        <gravity>1</gravity>
        <visual name='visual'>
          <pose frame=''>0 0 0 0 -0 0</pose>
          <geometry>
            <cylinder>
              <radius>0.1</radius>
              <length>0.05</length>
            </cylinder>
          </geometry>
          <material>
            <lighting>1</lighting>
            <script>
              <uri>file://media/materials/scripts/gazebo.material</uri>
              <name>Gazebo/Grey</name>
            </script>
            <shader type='pixel'>
              <normal_map>__default__</normal_map>
            </shader>
            <ambient>0.3 0.3 0.3 1</ambient>
            <diffuse>0.7 0.7 0.7 1</diffuse>
            <specular>0.01 0.01 0.01 1</specular>
            <emissive>0 0 0 1</emissive>
          </material>
          <transparency>0</transparency>
          <cast_shadows>1</cast_shadows>
        </visual>
        <collision name='collision'>
          <laser_retro>0</laser_retro>
          <max_contacts>10</max_contacts>
          <pose frame=''>0 0 0 0 -0 0</pose>
          <geometry>
            <cylinder>
              <radius>0.1</radius>
              <length>0.05</length>
            </cylinder>
          </geometry>
          <surface>
            <friction>
              <ode>
                <mu>1</mu>
                <mu2>1</mu2>
                <fdir1>0 0 0</fdir1>
                <slip1>0</slip1>
                <slip2>0</slip2>
              </ode>
              <torsional>
                <coefficient>1</coefficient>
                <patch_radius>0</patch_radius>
                <surface_radius>0</surface_radius>
                <use_patch_radius>1</use_patch_radius>
                <ode>
                  <slip>0</slip>
                </ode>
              </torsional>
            </friction>
            <bounce>
              <restitution_coefficient>0</restitution_coefficient>
              <threshold>1e+06</threshold>
            </bounce>
            <contact>
              <collide_without_contact>0</collide_without_contact>
              <collide_without_contact_bitmask>1</collide_without_contact_bitmask>
              <collide_bitmask>1</collide_bitmask>
              <ode>
                <soft_cfm>0</soft_cfm>
                <soft_erp>0.2</soft_erp>
                <kp>1e+13</kp>
                <kd>1</kd>
                <max_vel>0.01</max_vel>
                <min_depth>0</min_depth>
              </ode>
              <bullet>
                <split_impulse>1</split_impulse>
                <split_impulse_penetration_threshold>-0.01</split_impulse_penetration_threshold>
                <soft_cfm>0</soft_cfm>
                <soft_erp>0.2</soft_erp>
                <kp>1e+13</kp>
                <kd>1</kd>
              </bullet>
            </contact>
          </surface>
        </collision>
      </link>
      <link name='link_4_clone_1'>
        <pose frame=''>0.2 0.17501 0 1.5707 -0 0</pose>
        <inertial>
          <mass>1</mass>
          <inertia>
            <ixx>0.145833</ixx>
            <ixy>0</ixy>
            <ixz>0</ixz>
            <iyy>0.145833</iyy>
            <iyz>0</iyz>
            <izz>0.125</izz>
          </inertia>
          <pose frame=''>0 0 0 0 -0 0</pose>
        </inertial>
        <self_collide>0</self_collide>
        <kinematic>0</kinematic>
        <visual name='visual'>
          <pose frame=''>0 0 0 0 -0 0</pose>
          <geometry>
            <cylinder>
              <radius>0.1</radius>
              <length>0.05</length>
            </cylinder>
          </geometry>
          <material>
            <lighting>1</lighting>
            <script>
              <uri>file://media/materials/scripts/gazebo.material</uri>
              <name>Gazebo/Grey</name>
            </script>
            <shader type='pixel'>
              <normal_map>__default__</normal_map>
            </shader>
            <ambient>0.3 0.3 0.3 1</ambient>
            <diffuse>0.7 0.7 0.7 1</diffuse>
            <specular>0.01 0.01 0.01 1</specular>
            <emissive>0 0 0 1</emissive>
          </material>
          <transparency>0</transparency>
          <cast_shadows>1</cast_shadows>
        </visual>
        <collision name='collision'>
          <laser_retro>0</laser_retro>
          <max_contacts>10</max_contacts>
          <pose frame=''>0 0 0 0 -0 0</pose>
          <geometry>
            <cylinder>
              <radius>0.1</radius>
              <length>0.05</length>
            </cylinder>
          </geometry>
          <surface>
            <friction>
              <ode>
                <mu>1</mu>
                <mu2>1</mu2>
                <fdir1>0 0 0</fdir1>
                <slip1>0</slip1>
                <slip2>0</slip2>
              </ode>
              <torsional>
                <coefficient>1</coefficient>
                <patch_radius>0</patch_radius>
                <surface_radius>0</surface_radius>
                <use_patch_radius>1</use_patch_radius>
                <ode>
                  <slip>0</slip>
                </ode>
              </torsional>
            </friction>
            <bounce>
              <restitution_coefficient>0</restitution_coefficient>
              <threshold>1e+06</threshold>
            </bounce>
            <contact>
              <collide_without_contact>0</collide_without_contact>
              <collide_without_contact_bitmask>1</collide_without_contact_bitmask>
              <collide_bitmask>1</collide_bitmask>
              <ode>
                <soft_cfm>0</soft_cfm>
                <soft_erp>0.2</soft_erp>
                <kp>1e+13</kp>
                <kd>1</kd>
                <max_vel>0.01</max_vel>
                <min_depth>0</min_depth>
              </ode>
              <bullet>
                <split_impulse>1</split_impulse>
                <split_impulse_penetration_threshold>-0.01</split_impulse_penetration_threshold>
                <soft_cfm>0</soft_cfm>
                <soft_erp>0.2</soft_erp>
                <kp>1e+13</kp>
                <kd>1</kd>
              </bullet>
            </contact>
          </surface>
        </collision>
      </link>
      <joint name='link_1_JOINT_3' type='revolute'>
        <parent>link_1</parent>
        <child>link_4_clone</child>
        <pose frame=''>0 0 0 -0.01 0 0</pose>
        <axis>
          <xyz>0 0 1</xyz>
          <use_parent_model_frame>0</use_parent_model_frame>
          <limit>
            <lower>-1.79769e+308</lower>
            <upper>1.79769e+308</upper>
            <effort>-1</effort>
            <velocity>-1</velocity>
          </limit>
          <dynamics>
            <spring_reference>0</spring_reference>
            <spring_stiffness>0</spring_stiffness>
            <damping>0</damping>
            <friction>0</friction>
          </dynamics>
        </axis>
        <physics>
          <ode>
            <limit>
              <cfm>0</cfm>
              <erp>0.2</erp>
            </limit>
            <suspension>
              <cfm>0</cfm>
              <erp>0.2</erp>
            </suspension>
          </ode>
        </physics>
      </joint>
      <joint name='link_1_JOINT_4' type='revolute'>
        <parent>link_1</parent>
        <child>link_4</child>
        <pose frame=''>0 0 0 0 -0 0</pose>
        <axis>
          <xyz>0 0 1</xyz>
          <use_parent_model_frame>0</use_parent_model_frame>
          <limit>
            <lower>-1.79769e+308</lower>
            <upper>1.79769e+308</upper>
            <effort>-1</effort>
            <velocity>-1</velocity>
          </limit>
          <dynamics>
            <spring_reference>0</spring_reference>
            <spring_stiffness>0</spring_stiffness>
            <damping>0</damping>
            <friction>0</friction>
          </dynamics>
        </axis>
        <physics>
          <ode>
            <limit>
              <cfm>0</cfm>
              <erp>0.2</erp>
            </limit>
            <suspension>
              <cfm>0</cfm>
              <erp>0.2</erp>
            </suspension>
          </ode>
        </physics>
      </joint>
      <joint name='link_1_JOINT_5' type='revolute'>
        <parent>link_1</parent>
        <child>link_4_clone_0</child>
        <pose frame=''>0 0 0 0 -0 0</pose>
        <axis>
          <xyz>0 0 1</xyz>
          <use_parent_model_frame>0</use_parent_model_frame>
          <limit>
            <lower>-1.79769e+308</lower>
            <upper>1.79769e+308</upper>
            <effort>-1</effort>
            <velocity>-1</velocity>
          </limit>
          <dynamics>
            <spring_reference>0</spring_reference>
            <spring_stiffness>0</spring_stiffness>
            <damping>0</damping>
            <friction>0</friction>
          </dynamics>
        </axis>
        <physics>
          <ode>
            <limit>
              <cfm>0</cfm>
              <erp>0.2</erp>
            </limit>
            <suspension>
              <cfm>0</cfm>
              <erp>0.2</erp>
            </suspension>
          </ode>
        </physics>
      </joint>
      <joint name='link_1_JOINT_6' type='revolute'>
        <parent>link_1</parent>
        <child>link_4_clone_1</child>
        <pose frame=''>0 0 0 0 -0 0</pose>
        <axis>
          <xyz>0 0 1</xyz>
          <use_parent_model_frame>0</use_parent_model_frame>
          <limit>
            <lower>-1.79769e+308</lower>
            <upper>1.79769e+308</upper>
            <effort>-1</effort>
            <velocity>-1</velocity>
          </limit>
          <dynamics>
            <spring_reference>0</spring_reference>
            <spring_stiffness>0</spring_stiffness>
            <damping>0</damping>
          </dynamics>
        </axis>
        <physics>
          <ode>
            <limit>
              <cfm>0</cfm>
              <erp>0.2</erp>
            </limit>
            <suspension>
              <cfm>0</cfm>
              <erp>0.2</erp>
            </suspension>
          </ode>
        </physics>
      </joint>
      <static>0</static>
      <allow_auto_disable>1</allow_auto_disable>
      <pose frame=''>-1.55375 -0.561765 0 0 -0 0</pose>
    </model>
    <model name='youbot'>
      <model name='youbot'>
        <pose frame=''>-0 -0 0 0 -0 0</pose>
        <link name='base_footprint'>
          <pose frame=''>0 0 0 0 -0 0</pose>
          <inertial>
            <pose frame=''>0 0 -0.05 0 -0 0</pose>
            <inertia>
              <ixx>1</ixx>
              <ixy>0</ixy>
              <ixz>0</ixz>
              <iyy>1</iyy>
              <iyz>0</iyz>
              <izz>1</izz>
            </inertia>
            <mass>0.1</mass>
          </inertial>
          <collision name='base_footprint_geom'>
            <pose frame=''>0 0 -0.05 0 -0 0</pose>
            <geometry>
              <box>
                <size>0.001 0.001 0.001</size>
              </box>
            </geometry>
            <surface>
              <friction>
                <ode>
                  <mu>0</mu>
                  <mu2>0</mu2>
                  <fdir1>0 0 0</fdir1>
                  <slip1>0</slip1>
                  <slip2>0</slip2>
                </ode>
                <torsional>
                  <ode/>
                </torsional>
              </friction>
              <bounce>
                <restitution_coefficient>0</restitution_coefficient>
                <threshold>0</threshold>
              </bounce>
              <contact>
                <ode>
                  <soft_cfm>0</soft_cfm>
                  <soft_erp>0.2</soft_erp>
                  <kp>1e+13</kp>
                  <kd>1e+11</kd>
                  <max_vel>-1</max_vel>
                  <min_depth>0</min_depth>
                </ode>
              </contact>
            </surface>
            <laser_retro>0</laser_retro>
            <max_contacts>10</max_contacts>
          </collision>
          <visual name='base_footprint_geom_visual'>
            <pose frame=''>0 0 0 0 -0 0</pose>
            <geometry>
              <box>
                <size>0.001 0.001 0.001</size>
              </box>
            </geometry>
          </visual>
          <gravity>1</gravity>
          <self_collide>0</self_collide>
          <kinematic>0</kinematic>
        </link>
        <link name='base_link'>
          <pose frame=''>0 0 0 0 -0 0</pose>
          <inertial>
            <pose frame=''>0 0 0 0 -0 0</pose>
            <inertia>
              <ixx>5.65223</ixx>
              <ixy>-0.00972</ixy>
              <ixz>1.29399</ixz>
              <iyy>5.66947</iyy>
              <iyz>-0.00738</iyz>
              <izz>3.6832</izz>
            </inertia>
            <mass>22</mass>
          </inertial>
          <collision name='base_link_geom'>
            <pose frame=''>0 0 0 0 -0 0</pose>
            <geometry>
              <mesh>
                <uri>model://youbot/meshes/base/base_convex.stl</uri>
              </mesh>
            </geometry>
            <surface>
              <friction>
                <ode>
                  <mu>0</mu>
                  <mu2>0</mu2>
                  <fdir1>0 0 0</fdir1>
                  <slip1>0</slip1>
                  <slip2>0</slip2>
                </ode>
                <torsional>
                  <ode/>
                </torsional>
              </friction>
              <bounce>
                <restitution_coefficient>0</restitution_coefficient>
                <threshold>0</threshold>
              </bounce>
              <contact>
                <ode>
                  <soft_cfm>0</soft_cfm>
                  <soft_erp>0.2</soft_erp>
                  <kp>1e+13</kp>
                  <kd>1e+11</kd>
                  <max_vel>-1</max_vel>
                  <min_depth>0</min_depth>
                </ode>
              </contact>
            </surface>
            <laser_retro>0</laser_retro>
            <max_contacts>10</max_contacts>
          </collision>
          <visual name='base_link_geom_visual'>
            <pose frame=''>0 0 0 0 -0 0</pose>
            <geometry>
              <mesh>
                <uri>model://youbot/meshes/base/base.dae</uri>
              </mesh>
            </geometry>
          </visual>
          <gravity>1</gravity>
          <self_collide>0</self_collide>
          <kinematic>0</kinematic>
        </link>
        <link name='arm_link_0'>
          <pose frame=''>0.143 0 0.046 0 -0 0</pose>
          <inertial>
            <pose frame=''>0 0 0 0 -0 0</pose>
            <inertia>
              <ixx>0.01</ixx>
              <ixy>0</ixy>
              <ixz>0</ixz>
              <iyy>0.01</iyy>
              <iyz>0</iyz>
              <izz>0.01</izz>
            </inertia>
            <mass>0.845</mass>
          </inertial>
          <collision name='arm_link_0_geom'>
            <pose frame=''>0 0 0 0 -0 0</pose>
            <geometry>
              <mesh>
                <uri>model://youbot/meshes/arm/arm0_convex.stl</uri>
              </mesh>
            </geometry>
            <surface>
              <friction>
                <ode>
                  <mu>0</mu>
                  <mu2>0</mu2>
                  <fdir1>0 0 0</fdir1>
                  <slip1>0</slip1>
                  <slip2>0</slip2>
                </ode>
                <torsional>
                  <ode/>
                </torsional>
              </friction>
              <bounce>
                <restitution_coefficient>0</restitution_coefficient>
                <threshold>0</threshold>
              </bounce>
              <contact>
                <ode>
                  <soft_cfm>0</soft_cfm>
                  <soft_erp>0.2</soft_erp>
                  <kp>1e+13</kp>
                  <kd>1e+11</kd>
                  <max_vel>-1</max_vel>
                  <min_depth>0</min_depth>
                </ode>
              </contact>
            </surface>
            <laser_retro>0</laser_retro>
            <max_contacts>10</max_contacts>
          </collision>
          <visual name='arm_link_0_geom_visual'>
            <pose frame=''>0 0 0 0 -0 0</pose>
            <geometry>
              <mesh>
                <uri>model://youbot/meshes/arm/arm0.dae</uri>
              </mesh>
            </geometry>
            <material>
              <script>
                <uri>model://youbot/materials/scripts/youbot.material</uri>
                <name>youbot/DarkGrey</name>
              </script>
            </material>
          </visual>
          <gravity>1</gravity>
          <self_collide>0</self_collide>
          <kinematic>0</kinematic>
        </link>
        <link name='arm_link_1'>
          <pose frame=''>0.167 0 0.142 0 -0 2.96706</pose>
          <inertial>
            <pose frame=''>0.01489 0.00213 0.00213 0 -0 0</pose>
            <inertia>
              <ixx>0.003863</ixx>
              <ixy>-0.000979</ixy>
              <ixz>0</ixz>
              <iyy>0.006196</iyy>
              <iyz>0</iyz>
              <izz>0.006369</izz>
            </inertia>
            <mass>2.412</mass>
          </inertial>
          <collision name='arm_link_1_geom'>
            <pose frame=''>0 0 0 0 -0 0</pose>
            <geometry>
              <mesh>
                <uri>model://youbot/meshes/arm/arm1_convex.stl</uri>
              </mesh>
            </geometry>
            <surface>
              <friction>
                <ode>
                  <mu>0</mu>
                  <mu2>0</mu2>
                  <fdir1>0 0 0</fdir1>
                  <slip1>0</slip1>
                  <slip2>0</slip2>
                </ode>
                <torsional>
                  <ode/>
                </torsional>
              </friction>
              <bounce>
                <restitution_coefficient>0</restitution_coefficient>
                <threshold>0</threshold>
              </bounce>
              <contact>
                <ode>
                  <soft_cfm>0</soft_cfm>
                  <soft_erp>0.2</soft_erp>
                  <kp>1e+13</kp>
                  <kd>1e+11</kd>
                  <max_vel>-1</max_vel>
                  <min_depth>0</min_depth>
                </ode>
              </contact>
            </surface>
            <laser_retro>0</laser_retro>
            <max_contacts>10</max_contacts>
          </collision>
          <visual name='arm_link_1_geom_visual'>
            <pose frame=''>0 0 0 0 -0 0</pose>
            <geometry>
              <mesh>
                <uri>model://youbot/meshes/arm/arm1.dae</uri>
              </mesh>
            </geometry>
          </visual>
          <gravity>1</gravity>
          <self_collide>0</self_collide>
          <kinematic>0</kinematic>
        </link>
        <link name='arm_link_2'>
          <pose frame=''>0.134501 0.00573 0.161 0 -1.13446 2.96706</pose>
          <inertial>
            <pose frame=''>0.10453 0.0017 -0.00297 0 -0 0</pose>
            <inertia>
              <ixx>0.000823</ixx>
              <ixy>0</ixy>
              <ixz>-0</ixz>
              <iyy>0.004447</iyy>
              <iyz>0</iyz>
              <izz>0.004439</izz>
            </inertia>
            <mass>1.155</mass>
          </inertial>
          <collision name='arm_link_2_geom'>
            <pose frame=''>0 -0.032 0.078 0 -0 0</pose>
            <geometry>
              <mesh>
                <uri>model://youbot/meshes/arm/arm2_convex.stl</uri>
              </mesh>
            </geometry>
            <surface>
              <friction>
                <ode>
                  <mu>0</mu>
                  <mu2>0</mu2>
                  <fdir1>0 0 0</fdir1>
                  <slip1>0</slip1>
                  <slip2>0</slip2>
                </ode>
                <torsional>
                  <ode/>
                </torsional>
              </friction>
              <bounce>
                <restitution_coefficient>0</restitution_coefficient>
                <threshold>0</threshold>
              </bounce>
              <contact>
                <ode>
                  <soft_cfm>0</soft_cfm>
                  <soft_erp>0.2</soft_erp>
                  <kp>1e+13</kp>
                  <kd>1e+11</kd>
                  <max_vel>-1</max_vel>
                  <min_depth>0</min_depth>
                </ode>
              </contact>
            </surface>
            <laser_retro>0</laser_retro>
            <max_contacts>10</max_contacts>
          </collision>
          <visual name='arm_link_2_geom_visual'>
            <pose frame=''>0 -0.032 0.078 0 -0 0</pose>
            <geometry>
              <mesh>
                <uri>model://youbot/meshes/arm/arm2.dae</uri>
              </mesh>
            </geometry>
          </visual>
          <gravity>1</gravity>
          <self_collide>0</self_collide>
          <kinematic>0</kinematic>
        </link>
        <link name='arm_link_3'>
          <pose frame=''>0.272845 -0.018663 0.226506 -0 1.41372 2.96706</pose>
          <inertial>
            <pose frame=''>0.0001 0.0967 0.02107 0 -0 0</pose>
            <inertia>
              <ixx>0.002459</ixx>
              <ixy>0</ixy>
              <ixz>0</ixz>
              <iyy>0.002571</iyy>
              <iyz>-0</iyz>
              <izz>0.000535</izz>
            </inertia>
            <mass>0.934</mass>
          </inertial>
          <collision name='arm_link_3_geom'>
            <pose frame=''>0 0.028 0.079 0 -0 0</pose>
            <geometry>
              <mesh>
                <uri>model://youbot/meshes/arm/arm3_convex.stl</uri>
              </mesh>
            </geometry>
            <surface>
              <friction>
                <ode>
                  <mu>0</mu>
                  <mu2>0</mu2>
                  <fdir1>0 0 0</fdir1>
                  <slip1>0</slip1>
                  <slip2>0</slip2>
                </ode>
                <torsional>
                  <ode/>
                </torsional>
              </friction>
              <bounce>
                <restitution_coefficient>0</restitution_coefficient>
                <threshold>0</threshold>
              </bounce>
              <contact>
                <ode>
                  <soft_cfm>0</soft_cfm>
                  <soft_erp>0.2</soft_erp>
                  <kp>1e+13</kp>
                  <kd>1e+11</kd>
                  <max_vel>-1</max_vel>
                  <min_depth>0</min_depth>
                </ode>
              </contact>
            </surface>
            <laser_retro>0</laser_retro>
            <max_contacts>10</max_contacts>
          </collision>
          <visual name='arm_link_3_geom_visual'>
            <pose frame=''>0 0.028 0.079 0 -0 0</pose>
            <geometry>
              <mesh>
                <uri>model://youbot/meshes/arm/arm3.dae</uri>
              </mesh>
            </geometry>
          </visual>
          <gravity>1</gravity>
          <self_collide>0</self_collide>
          <kinematic>0</kinematic>
        </link>
        <link name='arm_link_4'>
          <pose frame=''>0.141533 0.004491 0.247624 0 -0.375246 2.96706</pose>
          <inertial>
            <pose frame=''>0.00011 0.05103 -0.02319 0 -0 0</pose>
            <inertia>
              <ixx>0.000869</ixx>
              <ixy>0</ixy>
              <ixz>-0</ixz>
              <iyy>0.001173</iyy>
              <iyz>-0.000231</iyz>
              <izz>0.001091</izz>
            </inertia>
            <mass>0.877</mass>
          </inertial>
          <collision name='arm_link_4_geom'>
            <pose frame=''>0 -0.01 0.029 0 -0 0</pose>
            <geometry>
              <mesh>
                <uri>model://youbot/meshes/arm/arm4_convex.stl</uri>
              </mesh>
            </geometry>
            <surface>
              <friction>
                <ode>
                  <mu>0</mu>
                  <mu2>0</mu2>
                  <fdir1>0 0 0</fdir1>
                  <slip1>0</slip1>
                  <slip2>0</slip2>
                </ode>
                <torsional>
                  <ode/>
                </torsional>
              </friction>
              <bounce>
                <restitution_coefficient>0</restitution_coefficient>
                <threshold>0</threshold>
              </bounce>
              <contact>
                <ode>
                  <soft_cfm>0</soft_cfm>
                  <soft_erp>0.2</soft_erp>
                  <kp>1e+13</kp>
                  <kd>1e+11</kd>
                  <max_vel>-1</max_vel>
                  <min_depth>0</min_depth>
                </ode>
              </contact>
            </surface>
            <laser_retro>0</laser_retro>
            <max_contacts>10</max_contacts>
          </collision>
          <visual name='arm_link_4_geom_visual'>
            <pose frame=''>0 -0.01 0.029 0 -0 0</pose>
            <geometry>
              <mesh>
                <uri>model://youbot/meshes/arm/arm4.dae</uri>
              </mesh>
            </geometry>
          </visual>
          <gravity>1</gravity>
          <self_collide>0</self_collide>
          <kinematic>0</kinematic>
        </link>
        <link name='arm_link_5'>
          <pose frame=''>0.190287 -0.004106 0.367846 -0.085052 0.365926 -0.408445</pose>
          <inertial>
            <pose frame=''>0 0.00115 -0.01683 0 -0 0</pose>
            <inertia>
              <ixx>0.00028</ixx>
              <ixy>0</ixy>
              <ixz>0</ixz>
              <iyy>0.000339</iyy>
              <iyz>0</iyz>
              <izz>0.000119</izz>
            </inertia>
            <mass>0.251</mass>
          </inertial>
          <collision name='arm_link_5_geom'>
            <pose frame=''>0.003 0 -0.034 0 -0 0</pose>
            <geometry>
              <mesh>
                <uri>model://youbot/meshes/arm/arm5_convex.stl</uri>
              </mesh>
            </geometry>
            <surface>
              <bounce>
                <restitution_coefficient>0</restitution_coefficient>
                <threshold>0</threshold>
              </bounce>
              <contact>
                <ode>
                  <soft_cfm>0</soft_cfm>
                  <soft_erp>0.2</soft_erp>
                  <kp>1e+13</kp>
                  <kd>1e+11</kd>
                  <max_vel>-1</max_vel>
                  <min_depth>0</min_depth>
                </ode>
              </contact>
              <friction>
                <torsional>
                  <ode/>
                </torsional>
                <ode/>
              </friction>
            </surface>
            <laser_retro>0</laser_retro>
            <max_contacts>10</max_contacts>
          </collision>
          <visual name='arm_link_5_geom_visual'>
            <pose frame=''>0.003 0 -0.034 0 -0 0</pose>
            <geometry>
              <mesh>
                <uri>model://youbot/meshes/arm/arm5.dae</uri>
              </mesh>
            </geometry>
          </visual>
          <gravity>1</gravity>
          <self_collide>0</self_collide>
          <kinematic>0</kinematic>
        </link>
        <link name='gripper_palm_link'>
          <pose frame=''>0.190287 -0.004106 0.367846 -0.085052 0.365926 -0.408445</pose>
          <inertial>
            <pose frame=''>0 0 0 0 -0 0</pose>
            <inertia>
              <ixx>0.01</ixx>
              <ixy>0</ixy>
              <ixz>0</ixz>
              <iyy>0.01</iyy>
              <iyz>0</iyz>
              <izz>0.01</izz>
            </inertia>
            <mass>0.1</mass>
          </inertial>
          <collision name='gripper_palm_link_geom'>
            <pose frame=''>0 0 0 0 -0 0</pose>
            <geometry>
              <mesh>
                <uri>model://youbot/meshes/gripper/palm_convex.stl</uri>
              </mesh>
            </geometry>
            <surface>
              <friction>
                <ode>
                  <mu>0</mu>
                  <mu2>0</mu2>
                  <fdir1>0 0 0</fdir1>
                  <slip1>0</slip1>
                  <slip2>0</slip2>
                </ode>
                <torsional>
                  <ode/>
                </torsional>
              </friction>
              <bounce>
                <restitution_coefficient>0</restitution_coefficient>
                <threshold>0</threshold>
              </bounce>
              <contact>
                <ode>
                  <soft_cfm>0</soft_cfm>
                  <soft_erp>0.2</soft_erp>
                  <kp>1e+13</kp>
                  <kd>1e+11</kd>
                  <max_vel>-1</max_vel>
                  <min_depth>0</min_depth>
                </ode>
              </contact>
            </surface>
            <laser_retro>0</laser_retro>
            <max_contacts>10</max_contacts>
          </collision>
          <visual name='gripper_palm_link_geom_visual'>
            <pose frame=''>0 0 0 0 -0 0</pose>
            <geometry>
              <mesh>
                <uri>model://youbot/meshes/gripper/palm.stl</uri>
              </mesh>
            </geometry>
            <material>
              <script>
                <uri>file://media/materials/scripts/gazebo.material</uri>
                <name>Gazebo/Black</name>
              </script>
            </material>
          </visual>
          <gravity>1</gravity>
          <self_collide>1</self_collide>
          <kinematic>0</kinematic>
        </link>
        <link name='gripper_finger_link_l'>
          <pose frame=''>0.21326 -0.001105 0.408579 0.085052 -0.365926 2.73315</pose>
          <inertial>
            <pose frame=''>0 -0.001 0 0 -0 0</pose>
            <inertia>
              <ixx>0.01</ixx>
              <ixy>0</ixy>
              <ixz>0</ixz>
              <iyy>0.01</iyy>
              <iyz>0</iyz>
              <izz>0.01</izz>
            </inertia>
            <mass>0.01</mass>
          </inertial>
          <collision name='gripper_finger_link_l_geom'>
            <pose frame=''>0 0 0 0 -0 0</pose>
            <geometry>
              <mesh>
                <uri>model://youbot/meshes/gripper/finger_convex.stl</uri>
              </mesh>
            </geometry>
            <surface>
              <bounce>
                <restitution_coefficient>0</restitution_coefficient>
                <threshold>0</threshold>
              </bounce>
              <contact>
                <ode>
                  <soft_cfm>0</soft_cfm>
                  <soft_erp>0.2</soft_erp>
                  <kp>1e+13</kp>
                  <kd>1e+11</kd>
                  <max_vel>-1</max_vel>
                  <min_depth>0</min_depth>
                </ode>
              </contact>
              <friction>
                <torsional>
                  <ode/>
                </torsional>
                <ode/>
              </friction>
            </surface>
            <laser_retro>0</laser_retro>
            <max_contacts>10</max_contacts>
          </collision>
          <visual name='gripper_finger_link_l_geom_visual'>
            <pose frame=''>0 0 0 0 -0 0</pose>
            <geometry>
              <mesh>
                <uri>model://youbot/meshes/gripper/finger.stl</uri>
              </mesh>
            </geometry>
          </visual>
          <gravity>1</gravity>
          <self_collide>0</self_collide>
          <kinematic>0</kinematic>
        </link>
        <link name='gripper_finger_link_r'>
          <pose frame=''>0.207375 -0.015929 0.409848 -0.085052 0.365926 -0.408445</pose>
          <inertial>
            <pose frame=''>0 -0.001 0 0 -0 0</pose>
            <inertia>
              <ixx>0.01</ixx>
              <ixy>0</ixy>
              <ixz>0</ixz>
              <iyy>0.01</iyy>
              <iyz>0</iyz>
              <izz>0.01</izz>
            </inertia>
            <mass>0.01</mass>
          </inertial>
          <collision name='gripper_finger_link_r_geom'>
            <pose frame=''>0 0 0 0 -0 0</pose>
            <geometry>
              <mesh>
                <uri>model://youbot/meshes/gripper/finger_convex.stl</uri>
              </mesh>
            </geometry>
            <surface>
              <bounce>
                <restitution_coefficient>0</restitution_coefficient>
                <threshold>0</threshold>
              </bounce>
              <contact>
                <ode>
                  <soft_cfm>0</soft_cfm>
                  <soft_erp>0.2</soft_erp>
                  <kp>1e+13</kp>
                  <kd>1e+11</kd>
                  <max_vel>-1</max_vel>
                  <min_depth>0</min_depth>
                </ode>
              </contact>
              <friction>
                <torsional>
                  <ode/>
                </torsional>
                <ode/>
              </friction>
            </surface>
            <laser_retro>0</laser_retro>
            <max_contacts>10</max_contacts>
          </collision>
          <visual name='gripper_finger_link_r_geom_visual'>
            <pose frame=''>0 0 0 0 -0 0</pose>
            <geometry>
              <mesh>
                <uri>model://youbot/meshes/gripper/finger.stl</uri>
              </mesh>
            </geometry>
          </visual>
          <gravity>1</gravity>
          <self_collide>0</self_collide>
          <kinematic>0</kinematic>
        </link>
        <link name='base_laser_front_link'>
          <pose frame=''>0.3 0 -0.03 0 -0 0</pose>
          <inertial>
            <pose frame=''>0 0 0 0 -0 0</pose>
            <inertia>
              <ixx>0.1</ixx>
              <ixy>0</ixy>
              <ixz>0</ixz>
              <iyy>0.1</iyy>
              <iyz>0</iyz>
              <izz>0.1</izz>
            </inertia>
            <mass>0.16</mass>
          </inertial>
          <collision name='base_laser_front_link_geom'>
            <pose frame=''>0 0 0 0 -0 0</pose>
            <geometry>
              <mesh>
                <uri>model://hokuyo/meshes/hokuyo_convex.stl</uri>
              </mesh>
            </geometry>
            <surface>
              <bounce>
                <restitution_coefficient>0</restitution_coefficient>
                <threshold>0</threshold>
              </bounce>
              <contact>
                <ode>
                  <soft_cfm>0</soft_cfm>
                  <soft_erp>0.2</soft_erp>
                  <kp>1e+13</kp>
                  <kd>1e+11</kd>
                  <max_vel>-1</max_vel>
                  <min_depth>0</min_depth>
                </ode>
              </contact>
              <friction>
                <torsional>
                  <ode/>
                </torsional>
                <ode/>
              </friction>
            </surface>
            <laser_retro>0</laser_retro>
            <max_contacts>10</max_contacts>
          </collision>
          <visual name='base_laser_front_link_geom_visual'>
            <pose frame=''>0 0 0 0 -0 0</pose>
            <geometry>
              <mesh>
                <uri>model://hokuyo/meshes/hokuyo.dae</uri>
              </mesh>
            </geometry>
          </visual>
          <sensor name='base_laser_front' type='ray'>
            <pose frame=''>0 0 0 0 -0 0</pose>
            <ray>
              <scan>
                <horizontal>
                  <samples>640</samples>
                  <resolution>1</resolution>
                  <min_angle>-1.57</min_angle>
                  <max_angle>1.57</max_angle>
                </horizontal>
                <vertical>
                  <samples>1</samples>
                  <min_angle>0</min_angle>
                  <max_angle>0</max_angle>
                </vertical>
              </scan>
              <range>
                <min>0.05</min>
                <max>5.6</max>
                <resolution>0.36</resolution>
              </range>
            </ray>
            <always_on>0</always_on>
            <update_rate>10</update_rate>
            <visualize>0</visualize>
          </sensor>
          <gravity>1</gravity>
          <self_collide>0</self_collide>
          <kinematic>0</kinematic>
        </link>
        <link name='caster_link_bl'>
          <pose frame=''>-0.228 0.158 -0.034 0 -0 0</pose>
          <inertial>
            <pose frame=''>0 0 0 0 -0 0</pose>
            <inertia>
              <ixx>0.012412</ixx>
              <ixy>-0.000712</ixy>
              <ixz>0.000503</ixz>
              <iyy>0.015218</iyy>
              <iyz>-4e-06</iyz>
              <izz>0.011764</izz>
            </inertia>
            <mass>0.1</mass>
          </inertial>
          <gravity>1</gravity>
          <self_collide>0</self_collide>
          <kinematic>0</kinematic>
        </link>
        <link name='wheel_link_bl'>
          <pose frame=''>-0.228 0.158 -0.034 0 -0 0</pose>
          <inertial>
            <pose frame=''>0 0 0 0 -0 0</pose>
            <inertia>
              <ixx>0.012412</ixx>
              <ixy>-0.000712</ixy>
              <ixz>0.000503</ixz>
              <iyy>0.015218</iyy>
              <iyz>-4e-06</iyz>
              <izz>0.011764</izz>
            </inertia>
            <mass>0.4</mass>
          </inertial>
          <collision name='wheel_link_bl_geom'>
            <pose frame=''>0 0 0 1.5708 -0 0</pose>
            <geometry>
              <cylinder>
                <radius>0.05</radius>
                <length>0.005</length>
              </cylinder>
            </geometry>
            <surface>
              <bounce>
                <restitution_coefficient>0</restitution_coefficient>
                <threshold>0</threshold>
              </bounce>
              <contact>
                <ode>
                  <soft_cfm>0</soft_cfm>
                  <soft_erp>0.2</soft_erp>
                  <kp>1e+13</kp>
                  <kd>1e+11</kd>
                  <max_vel>-1</max_vel>
                  <min_depth>0</min_depth>
                </ode>
              </contact>
              <friction>
                <torsional>
                  <ode/>
                </torsional>
                <ode/>
              </friction>
            </surface>
            <laser_retro>0</laser_retro>
            <max_contacts>10</max_contacts>
          </collision>
          <visual name='wheel_link_bl_geom_visual'>
            <pose frame=''>0 0 0 0 -0 0</pose>
            <geometry>
              <mesh>
                <uri>model://youbot/meshes/base/back-left_wheel.dae</uri>
              </mesh>
            </geometry>
            <material>
              <script>
                <uri>model://youbot/materials/scripts/youbot.material</uri>
                <name>youbot/Orange</name>
              </script>
            </material>
          </visual>
          <gravity>1</gravity>
          <self_collide>0</self_collide>
          <kinematic>0</kinematic>
        </link>
        <link name='caster_link_br'>
          <pose frame=''>-0.228 -0.158 -0.034 0 -0 0</pose>
          <inertial>
            <pose frame=''>0 0 0 0 -0 0</pose>
            <inertia>
              <ixx>0.012412</ixx>
              <ixy>-0.000712</ixy>
              <ixz>0.000503</ixz>
              <iyy>0.015218</iyy>
              <iyz>-4e-06</iyz>
              <izz>0.011764</izz>
            </inertia>
            <mass>0.1</mass>
          </inertial>
          <gravity>1</gravity>
          <self_collide>0</self_collide>
          <kinematic>0</kinematic>
        </link>
        <link name='wheel_link_br'>
          <pose frame=''>-0.228 -0.158 -0.034 0 -0 0</pose>
          <inertial>
            <pose frame=''>0 0 0 0 -0 0</pose>
            <inertia>
              <ixx>0.012412</ixx>
              <ixy>-0.000712</ixy>
              <ixz>0.000503</ixz>
              <iyy>0.015218</iyy>
              <iyz>-4e-06</iyz>
              <izz>0.011764</izz>
            </inertia>
            <mass>0.4</mass>
          </inertial>
          <collision name='wheel_link_br_geom'>
            <pose frame=''>0 0 0 1.5708 -0 0</pose>
            <geometry>
              <cylinder>
                <radius>0.05</radius>
                <length>0.005</length>
              </cylinder>
            </geometry>
            <surface>
              <bounce>
                <restitution_coefficient>0</restitution_coefficient>
                <threshold>0</threshold>
              </bounce>
              <contact>
                <ode>
                  <soft_cfm>0</soft_cfm>
                  <soft_erp>0.2</soft_erp>
                  <kp>1e+13</kp>
                  <kd>1e+11</kd>
                  <max_vel>-1</max_vel>
                  <min_depth>0</min_depth>
                </ode>
              </contact>
              <friction>
                <torsional>
                  <ode/>
                </torsional>
                <ode/>
              </friction>
            </surface>
            <laser_retro>0</laser_retro>
            <max_contacts>10</max_contacts>
          </collision>
          <visual name='wheel_link_br_geom_visual'>
            <pose frame=''>0 0 0 0 -0 0</pose>
            <geometry>
              <mesh>
                <uri>model://youbot/meshes/base/back-right_wheel.dae</uri>
              </mesh>
            </geometry>
            <material>
              <script>
                <uri>model://youbot/materials/scripts/youbot.material</uri>
                <name>youbot/Orange</name>
              </script>
            </material>
          </visual>
          <gravity>1</gravity>
          <self_collide>0</self_collide>
          <kinematic>0</kinematic>
        </link>
        <link name='caster_link_fl'>
          <pose frame=''>0.228 0.158 -0.034 0 -0 0</pose>
          <inertial>
            <pose frame=''>0 0 0 0 -0 0</pose>
            <inertia>
              <ixx>0.012412</ixx>
              <ixy>-0.000712</ixy>
              <ixz>0.000503</ixz>
              <iyy>0.015218</iyy>
              <iyz>-4e-06</iyz>
              <izz>0.011764</izz>
            </inertia>
            <mass>0.1</mass>
          </inertial>
          <gravity>1</gravity>
          <self_collide>0</self_collide>
          <kinematic>0</kinematic>
        </link>
        <link name='wheel_link_fl'>
          <pose frame=''>0.228 0.158 -0.034 0 -0 0</pose>
          <inertial>
            <pose frame=''>0 0 0 0 -0 0</pose>
            <inertia>
              <ixx>0.012412</ixx>
              <ixy>-0.000712</ixy>
              <ixz>0.000503</ixz>
              <iyy>0.015218</iyy>
              <iyz>-4e-06</iyz>
              <izz>0.011764</izz>
            </inertia>
            <mass>0.4</mass>
          </inertial>
          <collision name='wheel_link_fl_geom'>
            <pose frame=''>0 0 0 1.5708 -0 0</pose>
            <geometry>
              <cylinder>
                <radius>0.05</radius>
                <length>0.005</length>
              </cylinder>
            </geometry>
            <surface>
              <bounce>
                <restitution_coefficient>0</restitution_coefficient>
                <threshold>0</threshold>
              </bounce>
              <contact>
                <ode>
                  <soft_cfm>0</soft_cfm>
                  <soft_erp>0.2</soft_erp>
                  <kp>1e+13</kp>
                  <kd>1e+11</kd>
                  <max_vel>-1</max_vel>
                  <min_depth>0</min_depth>
                </ode>
              </contact>
              <friction>
                <torsional>
                  <ode/>
                </torsional>
                <ode/>
              </friction>
            </surface>
            <laser_retro>0</laser_retro>
            <max_contacts>10</max_contacts>
          </collision>
          <visual name='wheel_link_fl_geom_visual'>
            <pose frame=''>0 0 0 0 -0 0</pose>
            <geometry>
              <mesh>
                <uri>model://youbot/meshes/base/front-left_wheel.dae</uri>
              </mesh>
            </geometry>
            <material>
              <script>
                <uri>model://youbot/materials/scripts/youbot.material</uri>
                <name>youbot/Orange</name>
              </script>
            </material>
          </visual>
          <gravity>1</gravity>
          <self_collide>0</self_collide>
          <kinematic>0</kinematic>
        </link>
        <link name='caster_link_fr'>
          <pose frame=''>0.228 -0.158 -0.034 0 -0 0</pose>
          <inertial>
            <pose frame=''>0 0 0 0 -0 0</pose>
            <inertia>
              <ixx>0.012412</ixx>
              <ixy>-0.000712</ixy>
              <ixz>0.000503</ixz>
              <iyy>0.015218</iyy>
              <iyz>-4e-06</iyz>
              <izz>0.011764</izz>
            </inertia>
            <mass>0.1</mass>
          </inertial>
          <gravity>1</gravity>
          <self_collide>0</self_collide>
          <kinematic>0</kinematic>
        </link>
        <link name='wheel_link_fr'>
          <pose frame=''>0.228 -0.158 -0.034 0 -0 0</pose>
          <inertial>
            <pose frame=''>0 0 0 0 -0 0</pose>
            <inertia>
              <ixx>0.012412</ixx>
              <ixy>-0.000712</ixy>
              <ixz>0.000503</ixz>
              <iyy>0.015218</iyy>
              <iyz>-4e-06</iyz>
              <izz>0.011764</izz>
            </inertia>
            <mass>0.4</mass>
          </inertial>
          <collision name='wheel_link_fr_geom'>
            <pose frame=''>0 0 0 1.5708 -0 0</pose>
            <geometry>
              <cylinder>
                <radius>0.05</radius>
                <length>0.005</length>
              </cylinder>
            </geometry>
            <surface>
              <bounce>
                <restitution_coefficient>0</restitution_coefficient>
                <threshold>0</threshold>
              </bounce>
              <contact>
                <ode>
                  <soft_cfm>0</soft_cfm>
                  <soft_erp>0.2</soft_erp>
                  <kp>1e+13</kp>
                  <kd>1e+11</kd>
                  <max_vel>-1</max_vel>
                  <min_depth>0</min_depth>
                </ode>
              </contact>
              <friction>
                <torsional>
                  <ode/>
                </torsional>
                <ode/>
              </friction>
            </surface>
            <laser_retro>0</laser_retro>
            <max_contacts>10</max_contacts>
          </collision>
          <visual name='wheel_link_fr_geom_visual'>
            <pose frame=''>0 0 0 0 -0 0</pose>
            <geometry>
              <mesh>
                <uri>model://youbot/meshes/base/front-right_wheel.dae</uri>
              </mesh>
            </geometry>
            <material>
              <script>
                <uri>model://youbot/materials/scripts/youbot.material</uri>
                <name>youbot/Orange</name>
              </script>
            </material>
          </visual>
          <gravity>1</gravity>
          <self_collide>0</self_collide>
          <kinematic>0</kinematic>
        </link>
        <link name='plate_link'>
          <pose frame=''>-0.159 0 0.046 0 -0 0</pose>
          <inertial>
            <pose frame=''>0 0 0 0 -0 0</pose>
            <inertia>
              <ixx>0.01</ixx>
              <ixy>0</ixy>
              <ixz>0</ixz>
              <iyy>0.01</iyy>
              <iyz>0</iyz>
              <izz>0.01</izz>
            </inertia>
            <mass>1</mass>
          </inertial>
          <collision name='plate_link_geom'>
            <pose frame=''>0 0 0 0 -0 0</pose>
            <geometry>
              <mesh>
                <uri>model://youbot/meshes/plate/plate_convex.stl</uri>
              </mesh>
            </geometry>
            <surface>
              <bounce>
                <restitution_coefficient>0</restitution_coefficient>
                <threshold>0</threshold>
              </bounce>
              <contact>
                <ode>
                  <soft_cfm>0</soft_cfm>
                  <soft_erp>0.2</soft_erp>
                  <kp>1e+13</kp>
                  <kd>1e+11</kd>
                  <max_vel>-1</max_vel>
                  <min_depth>0</min_depth>
                </ode>
              </contact>
              <friction>
                <torsional>
                  <ode/>
                </torsional>
                <ode/>
              </friction>
            </surface>
            <laser_retro>0</laser_retro>
            <max_contacts>10</max_contacts>
          </collision>
          <visual name='plate_link_geom_visual'>
            <pose frame=''>0 0 0 0 -0 0</pose>
            <geometry>
              <mesh>
                <uri>model://youbot/meshes/plate/plate.dae</uri>
              </mesh>
            </geometry>
          </visual>
          <gravity>1</gravity>
          <self_collide>0</self_collide>
          <kinematic>0</kinematic>
        </link>
        <joint name='base_footprint_joint' type='revolute'>
          <pose frame=''>0 0 0 0 -0 0</pose>
          <parent>base_footprint</parent>
          <child>base_link</child>
          <axis>
            <dynamics>
              <damping>0</damping>
              <friction>0</friction>
              <spring_reference>0</spring_reference>
              <spring_stiffness>0</spring_stiffness>
            </dynamics>
            <limit>
              <lower>0</lower>
              <upper>0</upper>
              <effort>0</effort>
              <velocity>0</velocity>
            </limit>
            <xyz>0 0 1</xyz>
            <use_parent_model_frame>1</use_parent_model_frame>
          </axis>
        </joint>
        <joint name='arm_joint_0' type='revolute'>
          <pose frame=''>0 0 0 0 -0 0</pose>
          <parent>base_link</parent>
          <child>arm_link_0</child>
          <axis>
            <dynamics>
              <damping>0</damping>
              <friction>0</friction>
              <spring_reference>0</spring_reference>
              <spring_stiffness>0</spring_stiffness>
            </dynamics>
            <limit>
              <lower>0</lower>
              <upper>0</upper>
              <effort>0</effort>
              <velocity>0</velocity>
            </limit>
            <xyz>0 0 1</xyz>
            <use_parent_model_frame>1</use_parent_model_frame>
          </axis>
        </joint>
        <joint name='arm_joint_1' type='revolute'>
          <pose frame=''>0 0 0 0 -0 0</pose>
          <parent>arm_link_0</parent>
          <child>arm_link_1</child>
          <axis>
            <dynamics>
              <damping>1</damping>
              <friction>0</friction>
              <spring_reference>0</spring_reference>
              <spring_stiffness>0</spring_stiffness>
            </dynamics>
            <limit>
              <lower>0</lower>
              <upper>5.89921</upper>
              <effort>9.5</effort>
            </limit>
            <xyz>0 0 -1</xyz>
            <use_parent_model_frame>1</use_parent_model_frame>
          </axis>
        </joint>
        <joint name='arm_joint_2' type='revolute'>
          <pose frame=''>0 0 0 0 -0 0</pose>
          <parent>arm_link_1</parent>
          <child>arm_link_2</child>
          <axis>
            <dynamics>
              <damping>1</damping>
              <friction>0</friction>
              <spring_reference>0</spring_reference>
              <spring_stiffness>0</spring_stiffness>
            </dynamics>
            <limit>
              <lower>0</lower>
              <upper>2.70526</upper>
              <effort>9.5</effort>
              <velocity>-1</velocity>
            </limit>
            <xyz>-0.173648 -0.984808 0</xyz>
            <use_parent_model_frame>1</use_parent_model_frame>
          </axis>
        </joint>
        <joint name='arm_joint_3' type='revolute'>
          <pose frame=''>0 0 0 0 -0 0</pose>
          <parent>arm_link_2</parent>
          <child>arm_link_3</child>
          <axis>
            <dynamics>
              <damping>1</damping>
              <friction>0</friction>
              <spring_reference>0</spring_reference>
              <spring_stiffness>0</spring_stiffness>
            </dynamics>
            <limit>
              <lower>-5.18363</lower>
              <upper>0</upper>
              <effort>6</effort>
              <velocity>-1</velocity>
            </limit>
            <xyz>-0.173648 -0.984808 0</xyz>
            <use_parent_model_frame>1</use_parent_model_frame>
          </axis>
        </joint>
        <joint name='arm_joint_4' type='revolute'>
          <pose frame=''>0 0 0 0 -0 0</pose>
          <parent>arm_link_3</parent>
          <child>arm_link_4</child>
          <axis>
            <dynamics>
              <damping>1</damping>
              <friction>0</friction>
              <spring_reference>0</spring_reference>
              <spring_stiffness>0</spring_stiffness>
            </dynamics>
            <limit>
              <lower>0</lower>
              <upper>3.57793</upper>
              <effort>2</effort>
              <velocity>-1</velocity>
            </limit>
            <xyz>-0.173648 -0.984808 0</xyz>
            <use_parent_model_frame>1</use_parent_model_frame>
          </axis>
        </joint>
        <joint name='arm_joint_5' type='revolute'>
          <pose frame=''>0 0 0 0 -0 0</pose>
          <parent>arm_link_4</parent>
          <child>arm_link_5</child>
          <axis>
            <dynamics>
              <damping>1</damping>
              <friction>0</friction>
              <spring_reference>0</spring_reference>
              <spring_stiffness>0</spring_stiffness>
            </dynamics>
            <limit>
              <lower>0</lower>
              <upper>5.84685</upper>
              <effort>1</effort>
              <velocity>-1</velocity>
            </limit>
            <xyz>-0.360933 0.063642 -0.930418</xyz>
            <use_parent_model_frame>1</use_parent_model_frame>
          </axis>
        </joint>
        <joint name='gripper_palm_joint' type='revolute'>
          <pose frame=''>0 0 0 0 -0 0</pose>
          <parent>arm_link_5</parent>
          <child>gripper_palm_link</child>
          <axis>
            <dynamics>
              <damping>0</damping>
              <friction>0</friction>
              <spring_reference>0</spring_reference>
              <spring_stiffness>0</spring_stiffness>
            </dynamics>
            <limit>
              <lower>0</lower>
              <upper>0</upper>
              <effort>0</effort>
              <velocity>0</velocity>
            </limit>
            <xyz>0 0 1</xyz>
            <use_parent_model_frame>1</use_parent_model_frame>
          </axis>
        </joint>
        <joint name='gripper_finger_joint_l' type='prismatic'>
          <pose frame=''>0 0 0 0 -0 0</pose>
          <parent>gripper_palm_link</parent>
          <child>gripper_finger_link_l</child>
          <axis>
            <dynamics>
              <damping>1</damping>
              <friction>0</friction>
              <spring_reference>0</spring_reference>
              <spring_stiffness>0</spring_stiffness>
            </dynamics>
            <limit>
              <lower>0</lower>
              <upper>0.0115</upper>
              <effort>1</effort>
              <velocity>-1</velocity>
            </limit>
            <xyz>0.367852 0.926495 -0.079325</xyz>
            <use_parent_model_frame>1</use_parent_model_frame>
          </axis>
        </joint>
        <joint name='gripper_finger_joint_r' type='prismatic'>
          <pose frame=''>0 0 0 0 -0 0</pose>
          <parent>gripper_palm_link</parent>
          <child>gripper_finger_link_r</child>
          <axis>
            <dynamics>
              <damping>1</damping>
              <friction>0</friction>
              <spring_reference>0</spring_reference>
              <spring_stiffness>0</spring_stiffness>
            </dynamics>
            <limit>
              <lower>0</lower>
              <upper>0.0115</upper>
              <effort>1</effort>
              <velocity>-1</velocity>
            </limit>
            <xyz>-0.367852 -0.926495 0.079325</xyz>
            <use_parent_model_frame>1</use_parent_model_frame>
          </axis>
        </joint>
        <joint name='base_laser_front_hokuyo_urg04_laser_joint' type='revolute'>
          <pose frame=''>0 0 0 0 -0 0</pose>
          <parent>base_link</parent>
          <child>base_laser_front_link</child>
          <axis>
            <dynamics>
              <damping>0</damping>
              <friction>0</friction>
              <spring_reference>0</spring_reference>
              <spring_stiffness>0</spring_stiffness>
            </dynamics>
            <limit>
              <lower>0</lower>
              <upper>0</upper>
              <effort>0</effort>
              <velocity>0</velocity>
            </limit>
            <xyz>0 0 1</xyz>
            <use_parent_model_frame>1</use_parent_model_frame>
          </axis>
        </joint>
        <joint name='caster_joint_bl' type='revolute'>
          <pose frame=''>0 0 0 0 -0 0</pose>
          <parent>base_link</parent>
          <child>caster_link_bl</child>
          <axis>
            <dynamics>
              <damping>1</damping>
              <friction>0</friction>
              <spring_reference>0</spring_reference>
              <spring_stiffness>0</spring_stiffness>
            </dynamics>
            <limit>
              <effort>1</effort>
              <lower>-1e+16</lower>
              <upper>1e+16</upper>
            </limit>
            <xyz>0 0 1</xyz>
            <use_parent_model_frame>1</use_parent_model_frame>
          </axis>
        </joint>
        <joint name='wheel_joint_bl' type='revolute'>
          <pose frame=''>0 0 0 0 -0 0</pose>
          <parent>caster_link_bl</parent>
          <child>wheel_link_bl</child>
          <axis>
            <dynamics>
              <damping>1</damping>
              <friction>0</friction>
              <spring_reference>0</spring_reference>
              <spring_stiffness>0</spring_stiffness>
            </dynamics>
            <limit>
              <effort>1</effort>
              <lower>-1e+16</lower>
              <upper>1e+16</upper>
            </limit>
            <xyz>0 1 0</xyz>
            <use_parent_model_frame>1</use_parent_model_frame>
          </axis>
        </joint>
        <joint name='caster_joint_br' type='revolute'>
          <pose frame=''>0 0 0 0 -0 0</pose>
          <parent>base_link</parent>
          <child>caster_link_br</child>
          <axis>
            <dynamics>
              <damping>1</damping>
              <friction>0</friction>
              <spring_reference>0</spring_reference>
              <spring_stiffness>0</spring_stiffness>
            </dynamics>
            <limit>
              <effort>1</effort>
              <lower>-1e+16</lower>
              <upper>1e+16</upper>
            </limit>
            <xyz>0 0 1</xyz>
            <use_parent_model_frame>1</use_parent_model_frame>
          </axis>
        </joint>
        <joint name='wheel_joint_br' type='revolute'>
          <pose frame=''>0 0 0 0 -0 0</pose>
          <parent>caster_link_br</parent>
          <child>wheel_link_br</child>
          <axis>
            <dynamics>
              <damping>1</damping>
              <friction>0</friction>
              <spring_reference>0</spring_reference>
              <spring_stiffness>0</spring_stiffness>
            </dynamics>
            <limit>
              <effort>1</effort>
              <lower>-1e+16</lower>
              <upper>1e+16</upper>
            </limit>
            <xyz>0 1 0</xyz>
            <use_parent_model_frame>1</use_parent_model_frame>
          </axis>
        </joint>
        <joint name='caster_joint_fl' type='revolute'>
          <pose frame=''>0 0 0 0 -0 0</pose>
          <parent>base_link</parent>
          <child>caster_link_fl</child>
          <axis>
            <dynamics>
              <damping>1</damping>
              <friction>0</friction>
              <spring_reference>0</spring_reference>
              <spring_stiffness>0</spring_stiffness>
            </dynamics>
            <limit>
              <effort>1</effort>
              <lower>-1e+16</lower>
              <upper>1e+16</upper>
            </limit>
            <xyz>0 0 1</xyz>
            <use_parent_model_frame>1</use_parent_model_frame>
          </axis>
        </joint>
        <joint name='wheel_joint_fl' type='revolute'>
          <pose frame=''>0 0 0 0 -0 0</pose>
          <parent>caster_link_fl</parent>
          <child>wheel_link_fl</child>
          <axis>
            <dynamics>
              <damping>1</damping>
              <friction>0</friction>
              <spring_reference>0</spring_reference>
              <spring_stiffness>0</spring_stiffness>
            </dynamics>
            <limit>
              <effort>1</effort>
              <lower>-1e+16</lower>
              <upper>1e+16</upper>
            </limit>
            <xyz>0 1 0</xyz>
            <use_parent_model_frame>1</use_parent_model_frame>
          </axis>
        </joint>
        <joint name='caster_joint_fr' type='revolute'>
          <pose frame=''>0 0 0 0 -0 0</pose>
          <parent>base_link</parent>
          <child>caster_link_fr</child>
          <axis>
            <dynamics>
              <damping>1</damping>
              <friction>0</friction>
              <spring_reference>0</spring_reference>
              <spring_stiffness>0</spring_stiffness>
            </dynamics>
            <limit>
              <effort>1</effort>
              <lower>-1e+16</lower>
              <upper>1e+16</upper>
            </limit>
            <xyz>0 0 1</xyz>
            <use_parent_model_frame>1</use_parent_model_frame>
          </axis>
        </joint>
        <joint name='wheel_joint_fr' type='revolute'>
          <pose frame=''>0 0 0 0 -0 0</pose>
          <parent>caster_link_fr</parent>
          <child>wheel_link_fr</child>
          <axis>
            <dynamics>
              <damping>1</damping>
              <friction>0</friction>
              <spring_reference>0</spring_reference>
              <spring_stiffness>0</spring_stiffness>
            </dynamics>
            <limit>
              <effort>1</effort>
              <lower>-1e+16</lower>
              <upper>1e+16</upper>
            </limit>
            <xyz>0 1 0</xyz>
            <use_parent_model_frame>1</use_parent_model_frame>
          </axis>
        </joint>
        <joint name='plate_joint' type='revolute'>
          <parent>base_link</parent>
          <child>plate_link</child>
          <axis>
            <dynamics>
              <damping>0</damping>
              <friction>0</friction>
              <spring_reference>0</spring_reference>
              <spring_stiffness>0</spring_stiffness>
            </dynamics>
            <limit>
              <lower>0</lower>
              <upper>0</upper>
              <effort>0</effort>
              <velocity>0</velocity>
            </limit>
            <xyz>0 0 1</xyz>
            <use_parent_model_frame>1</use_parent_model_frame>
          </axis>
        </joint>
        <static>0</static>
      </model>
      <static>0</static>
      <allow_auto_disable>1</allow_auto_disable>
      <pose frame=''>-0.370869 -1.77956 0 0 -0 0</pose>
    </model>
    <state world_name='default'>
      <sim_time>110 176000000</sim_time>
      <real_time>111 138879305</real_time>
      <wall_time>1596456826 558902374</wall_time>
      <iterations>110176</iterations>
      <model name='4wheeled-car'>
        <pose frame=''>-1.55446 -0.561895 0.099998 2e-06 -2.2e-05 -0.004071</pose>
        <scale>1 1 1</scale>
        <link name='link_1'>
          <pose frame=''>-1.55446 -0.561894 0.099998 2e-06 -2.2e-05 -0.004071</pose>
          <velocity>-9e-06 -0.000128 -0.004761 0.001497 -0.022193 -0.000113</velocity>
          <acceleration>-0.008968 -0.129176 -8.27928 1.65247 1.5406 -0.115349</acceleration>
          <wrench>-0.008968 -0.129176 -8.27928 0 -0 0</wrench>
        </link>
        <link name='link_4'>
          <pose frame=''>-1.75517 -0.736092 0.099993 1.5707 -0.013363 -0.00407</pose>
          <velocity>-3.1e-05 -0.000107 -0.009475 0.001586 -0.000253 -0.000115</velocity>
          <acceleration>-0.032594 -0.10493 -9.47822 1.65079 -0.006731 -0.100729</acceleration>
          <wrench>-0.032594 -0.10493 -9.47822 0 -0 0</wrench>
        </link>
        <link name='link_4_clone'>
          <pose frame=''>-1.35517 -0.737717 0.100002 1.5707 0.000387 -0.004075</pose>
          <velocity>-2.7e-05 -0.000157 -0.000609 0.001585 -4.1e-05 -0.000337</velocity>
          <acceleration>-0.019325 -0.165035 -7.65322 1.66652 -0.009044 -0.141448</acceleration>
          <wrench>-0.019325 -0.165035 -7.65322 0 -0 0</wrench>
        </link>
        <link name='link_4_clone_0'>
          <pose frame=''>-1.75374 -0.386071 0.099994 1.5707 0.009819 -0.004072</pose>
          <velocity>1e-05 -0.000108 -0.008899 0.001588 6.9e-05 -0.000115</velocity>
          <acceleration>0.002246 -0.116476 -8.90826 1.67129 -0.006814 -0.097129</acceleration>
          <wrench>0.002246 -0.116476 -8.90826 0 -0 0</wrench>
        </link>
        <link name='link_4_clone_1'>
          <pose frame=''>-1.35374 -0.387701 0.100002 1.5707 0.010335 -0.004072</pose>
          <velocity>8e-06 -0.000158 -2.9e-05 0.001583 0.000104 -0.000115</velocity>
          <acceleration>0.000914 -0.170493 -6.9356 1.70744 0.044309 -0.099106</acceleration>
          <wrench>0.000914 -0.170493 -6.9356 0 -0 0</wrench>
        </link>
      </model>
      <model name='ground_plane'>
        <pose frame=''>0 0 0 0 -0 0</pose>
        <scale>1 1 1</scale>
        <link name='link'>
          <pose frame=''>0 0 0 0 -0 0</pose>
          <velocity>0 0 0 0 -0 0</velocity>
          <acceleration>0 0 0 0 -0 0</acceleration>
          <wrench>0 0 0 0 -0 0</wrench>
        </link>
      </model>
      <model name='mybuilding'>
        <pose frame=''>0.334103 -0.288985 0 0 -0 0</pose>
        <scale>1 1 1</scale>
        <link name='Wall_21'>
          <pose frame=''>-7.49386 -1.93461 0 0 0 -1.5708</pose>
          <velocity>0 0 0 0 -0 0</velocity>
          <acceleration>0 0 0 0 -0 0</acceleration>
          <wrench>0 0 0 0 -0 0</wrench>
        </link>
        <link name='Wall_22'>
          <pose frame=''>-5.81887 -3.48461 0 0 -0 0</pose>
          <velocity>0 0 0 0 -0 0</velocity>
          <acceleration>0 0 0 0 -0 0</acceleration>
          <wrench>0 0 0 0 -0 0</wrench>
        </link>
        <link name='Wall_23'>
          <pose frame=''>-4.14387 -1.93461 0 0 -0 1.5708</pose>
          <velocity>0 0 0 0 -0 0</velocity>
          <acceleration>0 0 0 0 -0 0</acceleration>
          <wrench>0 0 0 0 -0 0</wrench>
        </link>
        <link name='Wall_25'>
          <pose frame=''>-5.81887 -0.384613 0 0 -0 0</pose>
          <velocity>0 0 0 0 -0 0</velocity>
          <acceleration>0 0 0 0 -0 0</acceleration>
          <wrench>0 0 0 0 -0 0</wrench>
        </link>
        <link name='Wall_30'>
          <pose frame=''>-7.49386 1.16538 0 0 -0 1.5708</pose>
          <velocity>0 0 0 0 -0 0</velocity>
          <acceleration>0 0 0 0 -0 0</acceleration>
          <wrench>0 0 0 0 -0 0</wrench>
        </link>
        <link name='Wall_31'>
          <pose frame=''>-5.81887 2.71538 0 0 -0 0</pose>
          <velocity>0 0 0 0 -0 0</velocity>
          <acceleration>0 0 0 0 -0 0</acceleration>
          <wrench>0 0 0 0 -0 0</wrench>
        </link>
        <link name='Wall_32'>
          <pose frame=''>-4.14387 1.79038 0 0 0 -1.5708</pose>
          <velocity>0 0 0 0 -0 0</velocity>
          <acceleration>0 0 0 0 -0 0</acceleration>
          <wrench>0 0 0 0 -0 0</wrench>
        </link>
        <link name='Wall_33'>
          <pose frame=''>-1.71886 0.865385 0 0 -0 0</pose>
          <velocity>0 0 0 0 -0 0</velocity>
          <acceleration>0 0 0 0 -0 0</acceleration>
          <wrench>0 0 0 0 -0 0</wrench>
        </link>
        <link name='Wall_34'>
          <pose frame=''>0.706138 1.91538 0 0 -0 1.5708</pose>
          <velocity>0 0 0 0 -0 0</velocity>
          <acceleration>0 0 0 0 -0 0</acceleration>
          <wrench>0 0 0 0 -0 0</wrench>
        </link>
        <link name='Wall_35'>
          <pose frame=''>1.88113 2.96538 0 0 -0 0</pose>
          <velocity>0 0 0 0 -0 0</velocity>
          <acceleration>0 0 0 0 -0 0</acceleration>
          <wrench>0 0 0 0 -0 0</wrench>
        </link>
        <link name='Wall_36'>
          <pose frame=''>3.05613 1.41538 0 0 0 -1.5708</pose>
          <velocity>0 0 0 0 -0 0</velocity>
          <acceleration>0 0 0 0 -0 0</acceleration>
          <wrench>0 0 0 0 -0 0</wrench>
        </link>
        <link name='Wall_38'>
          <pose frame=''>5.61171 1.05699 0 0 -0 0</pose>
          <velocity>0 0 0 0 -0 0</velocity>
          <acceleration>0 0 0 0 -0 0</acceleration>
          <wrench>0 0 0 0 -0 0</wrench>
        </link>
        <link name='Wall_39'>
          <pose frame=''>8.16171 -1.243 0 0 0 -1.5708</pose>
          <velocity>0 0 0 0 -0 0</velocity>
          <acceleration>0 0 0 0 -0 0</acceleration>
          <wrench>0 0 0 0 -0 0</wrench>
        </link>
        <link name='Wall_40'>
          <pose frame=''>2.00892 -3.51381 0 0 -0 3.13685</pose>
          <velocity>0 0 0 0 -0 0</velocity>
          <acceleration>0 0 0 0 -0 0</acceleration>
          <wrench>0 0 0 0 -0 0</wrench>
        </link>
        <link name='Wall_42'>
          <pose frame=''>3.05613 -1.80961 0 0 0 -1.5708</pose>
          <velocity>0 0 0 0 -0 0</velocity>
          <acceleration>0 0 0 0 -0 0</acceleration>
          <wrench>0 0 0 0 -0 0</wrench>
        </link>
      </model>
      <model name='youbot'>
        <pose frame=''>-0.371131 -1.77963 0.083978 1.5e-05 2.3e-05 0.000212</pose>
        <scale>1 1 1</scale>
        <model name='youbot'>
          <pose frame=''>-0.371131 -1.77963 0.083978 1.5e-05 2.3e-05 0.000212</pose>
          <scale>1 1 1</scale>
          <link name='arm_link_0'>
            <pose frame=''>-0.22813 -1.7796 0.129972 2.2e-05 2.4e-05 0.000211</pose>
            <velocity>-2.5e-05 -0.000107 0.000208 0.000301 -0.0003 -0.001348</velocity>
            <acceleration>0.06236 0.051413 0.012172 -1.82094 1.39864 -2.38491</acceleration>
            <wrench>0.052694 0.043444 0.010285 0 -0 0</wrench>
          </link>
          <link name='arm_link_1'>
            <pose frame=''>-0.204128 -1.7796 0.225972 -3.2e-05 -3.3e-05 2.95787</pose>
            <velocity>-9.5e-05 -0.000174 0.000223 0.000269 2.1e-05 -0.004318</velocity>
            <acceleration>0.094732 0.092156 0.057327 -2.58307 0.717928 3.03241</acceleration>
            <wrench>0.228494 0.222281 0.138272 0 -0 0</wrench>
          </link>
          <link name='arm_link_2'>
            <pose frame=''>-0.236573 -1.77357 0.244971 -0.000113 -1.1345 2.95794</pose>
            <velocity>-2.3e-05 1.5e-05 0.000203 -1.5e-05 -0.002536 -0.002797</velocity>
            <acceleration>0.130974 0.985002 0.17506 -2.74335 -0.005138 2.71368</acceleration>
            <wrench>0.151275 1.13768 0.202194 0 -0 0</wrench>
          </link>
          <link name='arm_link_3'>
            <pose frame=''>-0.098456 -1.79923 0.310453 0.000442 1.41372 2.95829</pose>
            <velocity>-0.000265 -0.000153 -0.000157 -0.002505 0.01952 -0.002368</velocity>
            <acceleration>0.319442 0.274994 3.24668 0.386303 -1.35471 2.50693</acceleration>
            <wrench>0.298359 0.256845 3.0324 0 -0 0</wrench>
          </link>
          <link name='arm_link_4'>
            <pose frame=''>-0.229547 -1.77487 0.331569 0.000106 -0.375287 2.95781</pose>
            <velocity>0.000249 0.000182 0.002452 -0.007464 0.002782 -0.002001</velocity>
            <acceleration>0.039349 0.15848 4.63528 -1.90742 0.665158 0.170491</acceleration>
            <wrench>0.034509 0.138987 4.06515 0 -0 0</wrench>
          </link>
          <link name='arm_link_5'>
            <pose frame=''>-0.180869 -1.78391 0.451789 -0.118774 0.356843 -0.512722</pose>
            <velocity>0.000665 0.000758 0.002358 -0.007895 0.000148 0.002237</velocity>
            <acceleration>0.693075 -1.60603 4.88919 2.46379 -0.720823 0.90378</acceleration>
            <wrench>0.173962 -0.403113 1.22719 0 -0 0</wrench>
          </link>
          <link name='base_footprint'>
            <pose frame=''>-0.371131 -1.77963 0.083978 1.5e-05 2.3e-05 0.000212</pose>
            <velocity>-1.2e-05 -0.000102 0.000135 0.000483 -0.000781 3e-06</velocity>
            <acceleration>-0.015299 0.005718 -0.121292 -0.00017 0.054931 -0.018081</acceleration>
            <wrench>-0.00153 0.000572 -0.012129 0 -0 0</wrench>
          </link>
          <link name='base_laser_front_link'>
            <pose frame=''>-0.071132 -1.77956 0.053971 1.5e-05 2.2e-05 0.000212</pose>
            <velocity>1e-05 -8.8e-05 0.000371 0.000483 -0.000783 2.1e-05</velocity>
            <acceleration>-0.017853 -0.004332 -0.144517 0.004803 0.054775 0.012716</acceleration>
            <wrench>-0.002856 -0.000693 -0.023123 0 -0 0</wrench>
          </link>
          <link name='base_link'>
            <pose frame=''>-0.371131 -1.77963 0.083978 1.5e-05 2.3e-05 0.000212</pose>
            <velocity>-1.2e-05 -0.000102 0.000134 0.000483 -0.000782 -0</velocity>
            <acceleration>-0.013267 0.00505 -0.123557 0.001265 0.055008 -0.023051</acceleration>
            <wrench>-0.291883 0.1111 -2.71825 0 -0 0</wrench>
          </link>
          <link name='caster_link_bl'>
            <pose frame=''>-0.599165 -1.62168 0.05 1.5e-05 2.2e-05 0.000191</pose>
            <velocity>2.7e-05 -5.1e-05 0.000252 0.000505 -0.000783 6e-06</velocity>
            <acceleration>-0.029638 0.001848 0.016437 0.009426 0.054507 -0.018634</acceleration>
            <wrench>-0.002964 0.000185 0.001644 0 -0 0</wrench>
          </link>
          <link name='caster_link_br'>
            <pose frame=''>-0.599098 -1.93768 0.05 1.5e-05 2.2e-05 0.000343</pose>
            <velocity>3.3e-05 -5.2e-05 0.000358 0.000508 -0.000784 -4e-05</velocity>
            <acceleration>-0.034341 0.001908 0.020435 0.009007 0.0538 -0.016703</acceleration>
            <wrench>-0.003434 0.000191 0.002043 0 -0 0</wrench>
          </link>
          <link name='caster_link_fl'>
            <pose frame=''>-0.143165 -1.62158 0.050002 1.5e-05 2.2e-05 0.000882</pose>
            <velocity>2.7e-05 -5.1e-05 0.000399 0.000501 -0.000786 -3e-06</velocity>
            <acceleration>-0.029813 -0.00434 0.014627 0.013534 0.053051 -0.018191</acceleration>
            <wrench>-0.002981 -0.000434 0.001463 0 -0 0</wrench>
          </link>
          <link name='caster_link_fr'>
            <pose frame=''>-0.143099 -1.93758 0.05 1.6e-05 2.2e-05 0.001026</pose>
            <velocity>3.2e-05 -5.3e-05 0.000493 0.000505 -0.000786 6e-06</velocity>
            <acceleration>-0.034441 -0.004348 0.018089 0.012944 0.053857 -0.018625</acceleration>
            <wrench>-0.003444 -0.000435 0.001809 0 -0 0</wrench>
          </link>
          <link name='gripper_finger_link_l'>
            <pose frame=''>-0.152232 -1.77155 0.491025 0.118777 -0.356845 2.62887</pose>
            <velocity>0.000805 0.001216 0.002211 -0.007458 0.000633 0.001628</velocity>
            <acceleration>2.10306 0.990037 4.25263 -1.23698 -1.02368 3.00459</acceleration>
            <wrench>0.021031 0.0099 0.042526 0 -0 0</wrench>
          </link>
          <link name='gripper_finger_link_r'>
            <pose frame=''>-0.164635 -1.79591 0.494078 -0.118777 0.356845 -0.51272</pose>
            <velocity>0.000847 0.001214 0.002402 -0.00743 0.00067 0.001619</velocity>
            <acceleration>2.19692 0.97438 4.50613 -1.03591 -1.06646 2.92392</acceleration>
            <wrench>0.021969 0.009744 0.045061 0 -0 0</wrench>
          </link>
          <link name='gripper_palm_link'>
            <pose frame=''>-0.180869 -1.78391 0.451789 -0.118777 0.356845 -0.51272</pose>
            <velocity>0.000712 0.000707 0.002338 -0.007472 0.000616 0.001632</velocity>
            <acceleration>0.721529 -1.7989 4.8318 -1.33081 -1.00347 3.04224</acceleration>
            <wrench>0.072153 -0.17989 0.48318 0 -0 0</wrench>
          </link>
          <link name='plate_link'>
            <pose frame=''>-0.53013 -1.77966 0.129981 1.5e-05 2.3e-05 0.000212</pose>
            <velocity>-4.9e-05 -0.000125 6e-06 0.000485 -0.000785 -4e-06</velocity>
            <acceleration>-0.013259 0.00713 -0.122686 0.004686 0.054894 -0.032682</acceleration>
            <wrench>-0.013259 0.00713 -0.122686 0 -0 0</wrench>
          </link>
          <link name='wheel_link_bl'>
            <pose frame=''>-0.599165 -1.62168 0.05 1.5e-05 -0.00963 0.000191</pose>
            <velocity>3.6e-05 -2.7e-05 0.000241 0.000557 0.000726 2e-06</velocity>
            <acceleration>-0.034673 -0.000205 0.009077 0.003093 -0.694222 -0.017922</acceleration>
            <wrench>-0.013869 -8.2e-05 0.003631 0 -0 0</wrench>
          </link>
          <link name='wheel_link_br'>
            <pose frame=''>-0.599098 -1.93768 0.049999 1.6e-05 -0.007492 0.000343</pose>
            <velocity>4.6e-05 -2.9e-05 0.000333 0.000561 0.000934 -4.5e-05</velocity>
            <acceleration>-0.036144 -0.000177 0.012553 0.002562 -0.722345 -0.016277</acceleration>
            <wrench>-0.014458 -7.1e-05 0.005021 0 -0 0</wrench>
          </link>
          <link name='wheel_link_fl'>
            <pose frame=''>-0.143165 -1.62158 0.05 1.6e-05 0.007447 0.000882</pose>
            <velocity>3.6e-05 -2.7e-05 0.000398 0.000549 0.000727 -7e-06</velocity>
            <acceleration>-0.035016 -0.001042 0.005976 0.017927 -0.70116 -0.017438</acceleration>
            <wrench>-0.014006 -0.000417 0.002391 0 -0 0</wrench>
          </link>
          <link name='wheel_link_fr'>
            <pose frame=''>-0.143099 -1.93758 0.049998 1.7e-05 0.009676 0.001026</pose>
            <velocity>4.5e-05 -3e-05 0.000478 0.000554 0.000905 2e-06</velocity>
            <acceleration>-0.036342 -0.001012 0.009355 0.017328 -0.726265 -0.018144</acceleration>
            <wrench>-0.014537 -0.000405 0.003742 0 -0 0</wrench>
          </link>
        </model>
      </model>
      <light name='sun'>
        <pose frame=''>0 0 10 0 -0 0</pose>
      </light>
    </state>
    <gui fullscreen='0'>
      <camera name='user_camera'>
        <pose frame=''>8.57179 -5.22596 8.53252 0 0.783643 2.85619</pose>
        <view_controller>orbit</view_controller>
        <projection_type>perspective</projection_type>
      </camera>
    </gui>
  </world>
</sdf>
