<?xml version='1.0'?>

<robot name="my_robot" xmlns:xacro="http://www.ros.org/wiki/xacro">
<xacro:include filename="$(find my_robot)/urdf/my_robot.gazebo" />
  <link name="robot_footprint"></link>
	
  <joint name="robot_footprint_joint" type="fixed">
    <origin xyz="0 0 0" rpy="0 0 0" />
    <parent link="robot_footprint"/>
    <child link="chassis" />
  </joint>

  <link name='chassis'>
    <pose>0 0 0.25 0 0 0</pose>

    <inertial>
      <mass value="1.0"/>
      <origin xyz="0.0 0 0" rpy=" 0 0 0"/>
      <inertia
          ixx="0.1" ixy="0" ixz="0"
          iyy="0.1" iyz="0"
          izz="0.1"
      />
    </inertial>

    <collision name='collision'>
      <origin xyz="0 0 0" rpy=" 0 0 0"/> 
      <geometry>
        <box size=".7 .2 .1"/>
      </geometry>
    </collision>

    <visual name='chassis_visual'>
      <origin xyz="0 0 0" rpy=" 0 0 0"/>
      <geometry>
        <box size=".7 .2 .1"/>
      </geometry>
    </visual>
  </link>

<link name='wheel_1'>
	<inertial>
		<mass value="1"/>
		<origin xyz="0 0 0" rpy="0 1.5707 1.5707"/>
		<inertia ixx="0.1" ixy="0" ixz="0" iyy="0.1" iyz="0" izz="0.1"/>
	</inertial>
	<collision name='wheel_1_collision'>
		<origin xyz="0 0 0" rpy="0 1.5707 1.5707"/>
		<geometry>
			<cylinder radius='0.249' length='0.05'/>
		</geometry>
	</collision>
	<visual>
		<origin xyz="0 0 0" rpy="0 1.5707 1.5707"/>
		<geometry>
			<cylinder radius='0.25' length='0.05'/>
		</geometry>
	</visual>
</link>

<link name='wheel_2'>
	<inertial>
		<mass value="1"/>
		<origin xyz="0 0 0" rpy="0 1.5707 1.5707"/>
		<inertia ixx="0.1" ixy="0" ixz="0" iyy="0.1" iyz="0" izz="0.1"/>
	</inertial>
	<collision name='wheel_2_collision'>
		<origin xyz="0 0 0" rpy="0 1.5707 1.5707"/>
		<geometry>
			<cylinder radius='0.249' length='0.05'/>
		</geometry>
	</collision>
	<visual>
		<origin xyz="0 0 0" rpy="0 1.5707 1.5707"/>
		<geometry>
			<cylinder radius='0.25' length='0.05'/>
		</geometry>
	</visual>
</link>

<link name='wheel_3'>
	<inertial>
		<mass value="1"/>
		<origin xyz="0 0 0" rpy="0 1.5707 1.5707"/>
		<inertia ixx="0.1" ixy="0" ixz="0" iyy="0.1" iyz="0" izz="0.1"/>
	</inertial>
	<collision name='wheel_3_collision'>
		<origin xyz="0 0 0" rpy="0 1.5707 1.5707"/>
		<geometry>
			<cylinder radius='0.249' length='0.05'/>
		</geometry>
	</collision>
	<visual>
		<origin xyz="0 0 0" rpy="0 1.5707 1.5707"/>
		<geometry>
			<cylinder radius='0.25' length='0.05'/>
		</geometry>
	</visual>
</link>

<link name='wheel_4'>
	<inertial>
		<mass value="1"/>
		<origin xyz="0 0 0" rpy="0 1.5707 1.5707"/>
		<inertia ixx="0.1" ixy="0" ixz="0" iyy="0.1" iyz="0" izz="0.1"/>
	</inertial>
	<collision name='wheel_4_collision'>
		<origin xyz="0 0 0" rpy="0 1.5707 1.5707"/>
		<geometry>
			<cylinder radius='0.249' length='0.05'/>
		</geometry>
	</collision>
	<visual>
		<origin xyz="0 0 0" rpy="0 1.5707 1.5707"/>
		<geometry>
			<cylinder radius='0.25' length='0.05'/>
		</geometry>
	</visual>
</link>


 <joint type="continuous" name="wheel_1_hinge">
    <origin xyz="0.3 0.15 0" rpy="0 0 0"/>
    <child link="wheel_1"/>
    <parent link="chassis"/>
    <axis xyz="0 1 0" rpy="0 0 0"/>
    <limit effort="10000" velocity="1000"/>
    <dynamics damping="1.0" friction="1.0"/>
  </joint>

 <joint type="continuous" name="wheel_2_hinge">
    <origin xyz="0.3 -0.15 0" rpy="0 0 0"/>
    <child link="wheel_2"/>
    <parent link="chassis"/>
    <axis xyz="0 1 0" rpy="0 0 0"/>
    <limit effort="10000" velocity="1000"/>
    <dynamics damping="1.0" friction="1.0"/>
  </joint>

 <joint type="continuous" name="wheel_3_hinge">
    <origin xyz="-0.3 0.15 0" rpy="0 0 0"/>
    <child link="wheel_3"/>
    <parent link="chassis"/>
    <axis xyz="0 1 0" rpy="0 0 0"/>
    <limit effort="10000" velocity="1000"/>
    <dynamics damping="1.0" friction="1.0"/>
  </joint>

 <joint type="continuous" name="wheel_4_hinge">
    <origin xyz="-0.3 -0.15 0" rpy="0 0 0"/>
    <child link="wheel_4"/>
    <parent link="chassis"/>
    <axis xyz="0 1 0" rpy="0 0 0"/>
    <limit effort="10000" velocity="1000"/>
    <dynamics damping="1.0" friction="1.0"/>
  </joint>

<link name='camera'>
	<inertial>
		<mass value="0.1"/>
		<origin xyz="0 0 0" rpy="0 0 0"/>
		<inertia ixx="1e-6" ixy="0" ixz="0" iyy="1e-6" iyz="0" izz="1e-6"/>
	</inertial>
	<collision name='camera_collision'>
		<origin xyz="0 0 0" rpy="0 0 0"/>
		<geometry>
			<box size="0.05 0.05 0.05"/>
		</geometry>
	</collision>
	<visual>
		<origin xyz="0 0 0" rpy="0 0 0"/>
		<geometry>
			<box size="0.05 0.05 0.05"/>
		</geometry>
	</visual>
	
</link>

<joint type="fixed" name='camera_joint'>
	<origin xyz="0.35 0 0" rpy="0 0 0"/>
	<child link="camera"/>
	<parent link="chassis"/>
	<axis xyz="0 1 0" rpy="0 0 0"/>
</joint>
	

<link name='hokuyo'>
	<visual>
		<origin xyz="0 0 0" rpy="0 0 0"/>
		<geometry>
			<mesh filename="package://my_robot/meshes/hokuyo.dae"/>
		</geometry>
	</visual>
	<collision>
		<origin xyz="0 0 0" rpy="0 0 0"/>
		<geometry>
			<box size="0.1 0.1 0.1"/> 
		</geometry>
	</collision>
	<inertial>
		<mass value="1e-5"/>
		<origin xyz="0 0 0" rpy="0 0 0"/>
		<inertia ixx="1e-6" ixy="0" ixz="0" iyy="1e-6" iyz="0" izz="1e-6"/>
	</inertial>
</link>

<joint type="fixed" name="hokuyo_joint">
	<origin xyz=".15 0 .1" rpy="0 0 0"/>
	<axis xyz="0 1 0" rpy="0 0 0"/>
	<child link="hokuyo"/>
	<parent link="chassis"/>
</joint>

<gazebo reference="wheel_1">
    <material>Gazebo/Red</material>
</gazebo>
<gazebo reference="wheel_2">
    <material>Gazebo/Orange</material>
</gazebo>
<gazebo reference="wheel_3">
    <material>Gazebo/Yellow</material>
</gazebo>
<gazebo reference="wheel_4">
    <material>Gazebo/Green</material>
</gazebo>
<gazebo reference="chassis">
	<material>Gazebo/Blue</material>
</gazebo>
<gazebo reference="camera">
	<material>Gazebo/White</material>
</gazebo>
<gazebo reference="hokuyo">
	<material>Gazebo/Black</material>
</gazebo>

</robot>

